<mujoco model="g1_12dof">
  <compiler angle="radian" meshdir="meshes/"/>

  <asset>
    <mesh name="pelvis" file="pelvis.STL"/>
    <mesh name="pelvis_contour_link" file="pelvis_contour_link.STL"/>
    <mesh name="left_hip_pitch_link" file="left_hip_pitch_link.STL"/>
    <mesh name="left_hip_roll_link" file="left_hip_roll_link.STL"/>
    <mesh name="left_hip_yaw_link" file="left_hip_yaw_link.STL"/>
    <mesh name="left_knee_link" file="left_knee_link.STL"/>
    <mesh name="left_ankle_pitch_link" file="left_ankle_pitch_link.STL"/>
    <mesh name="left_ankle_roll_link" file="left_ankle_roll_link.STL"/>
    <mesh name="right_hip_pitch_link" file="right_hip_pitch_link.STL"/>
    <mesh name="right_hip_roll_link" file="right_hip_roll_link.STL"/>
    <mesh name="right_hip_yaw_link" file="right_hip_yaw_link.STL"/>
    <mesh name="right_knee_link" file="right_knee_link.STL"/>
    <mesh name="right_ankle_pitch_link" file="right_ankle_pitch_link.STL"/>
    <mesh name="right_ankle_roll_link" file="right_ankle_roll_link.STL"/>
    <mesh name="torso_link_23dof_rev_1_0" file="torso_link_23dof_rev_1_0.STL"/>
    <mesh name="logo_link" file="logo_link.STL"/>
    <mesh name="head_link" file="head_link.STL"/>
    <mesh name="left_shoulder_pitch_link" file="left_shoulder_pitch_link.STL"/>
    <mesh name="left_shoulder_roll_link" file="left_shoulder_roll_link.STL"/>
    <mesh name="left_shoulder_yaw_link" file="left_shoulder_yaw_link.STL"/>
    <mesh name="left_elbow_link" file="left_elbow_link.STL"/>
    <mesh name="left_wrist_roll_rubber_hand" file="left_wrist_roll_rubber_hand.STL"/>
    <mesh name="right_shoulder_pitch_link" file="right_shoulder_pitch_link.STL"/>
    <mesh name="right_shoulder_roll_link" file="right_shoulder_roll_link.STL"/>
    <mesh name="right_shoulder_yaw_link" file="right_shoulder_yaw_link.STL"/>
    <mesh name="right_elbow_link" file="right_elbow_link.STL"/>
    <mesh name="right_wrist_roll_rubber_hand" file="right_wrist_roll_rubber_hand.STL"/>
  </asset>

  <worldbody>
    <geom type="mesh" contype="0" conaffinity="0" group="1" density="0" rgba="0.2 0.2 0.2 1" mesh="pelvis"/>
    <geom type="mesh" contype="0" conaffinity="0" group="1" density="0" rgba="0.7 0.7 0.7 1" mesh="pelvis_contour_link"/>
    <geom type="mesh" rgba="0.7 0.7 0.7 1" mesh="pelvis_contour_link"/>
    <geom type="mesh" contype="0" conaffinity="0" group="1" density="0" rgba="0.7 0.7 0.7 1" mesh="torso_link_23dof_rev_1_0"/>
    <geom type="mesh" rgba="0.7 0.7 0.7 1" mesh="torso_link_23dof_rev_1_0"/>
    <geom type="mesh" contype="0" conaffinity="0" group="1" density="0" rgba="0.2 0.2 0.2 1" mesh="logo_link"/>
    <geom type="mesh" rgba="0.2 0.2 0.2 1" mesh="logo_link"/>
    <geom type="mesh" contype="0" conaffinity="0" group="1" density="0" rgba="0.2 0.2 0.2 1" mesh="head_link"/>
    <geom type="mesh" rgba="0.2 0.2 0.2 1" mesh="head_link"/>
    <geom pos="-7.2e-06 0.10022 0.29178" quat="0.990264 0.139201 1.38722e-05 -9.86868e-05" type="mesh" contype="0" conaffinity="0" group="1" density="0" rgba="0.7 0.7 0.7 1" mesh="left_shoulder_pitch_link"/>
    <geom size="0.03 0.025" pos="7.72569e-07 0.141427 0.293195" quat="0.700213 0.0985001 0.700232 0.0983605" type="cylinder" rgba="0.7 0.7 0.7 1"/>
    <geom pos="3.73942e-07 0.14056 0.288961" quat="1 3.00026e-05 2.74716e-05 -9.57958e-05" type="mesh" contype="0" conaffinity="0" group="1" density="0" rgba="0.7 0.7 0.7 1" mesh="left_shoulder_roll_link"/>
    <geom size="0.03 0.015" pos="-0.00400139 0.146564 0.235962" quat="1 3.00026e-05 2.74716e-05 -9.57958e-05" type="cylinder" rgba="0.7 0.7 0.7 1"/>
    <geom pos="-4.10007e-06 0.146807 0.185762" quat="1 3.00026e-05 2.74716e-05 -9.57958e-05" type="mesh" contype="0" conaffinity="0" group="1" density="0" rgba="0.7 0.7 0.7 1" mesh="left_shoulder_yaw_link"/>
    <geom pos="-4.10007e-06 0.146807 0.185762" quat="1 3.00026e-05 2.74716e-05 -9.57958e-05" type="mesh" rgba="0.7 0.7 0.7 1" mesh="left_shoulder_yaw_link"/>
    <geom pos="0.0157745 0.146808 0.105243" quat="1 3.00026e-05 2.74716e-05 -9.57958e-05" type="mesh" contype="0" conaffinity="0" group="1" density="0" rgba="0.7 0.7 0.7 1" mesh="left_elbow_link"/>
    <geom pos="0.0157745 0.146808 0.105243" quat="1 3.00026e-05 2.74716e-05 -9.57958e-05" type="mesh" rgba="0.7 0.7 0.7 1" mesh="left_elbow_link"/>
    <geom pos="0.115774 0.148678 0.0952374" quat="1 3.00026e-05 2.74716e-05 -9.57958e-05" type="mesh" contype="0" conaffinity="0" group="1" density="0" rgba="0.7 0.7 0.7 1" mesh="left_wrist_roll_rubber_hand"/>
    <geom pos="0.115774 0.148678 0.0952374" quat="1 3.00026e-05 2.74716e-05 -9.57958e-05" type="mesh" rgba="0.7 0.7 0.7 1" mesh="left_wrist_roll_rubber_hand"/>
    <geom pos="-7.2e-06 -0.10021 0.29178" quat="0.990264 -0.139201 1.38722e-05 9.86868e-05" type="mesh" contype="0" conaffinity="0" group="1" density="0" rgba="0.7 0.7 0.7 1" mesh="right_shoulder_pitch_link"/>
    <geom size="0.03 0.025" pos="7.72569e-07 -0.141417 0.293195" quat="0.700213 -0.0985001 0.700232 -0.0983605" type="cylinder" rgba="0.7 0.7 0.7 1"/>
    <geom pos="3.73942e-07 -0.14055 0.288961" quat="1 -3.00026e-05 2.74716e-05 9.57958e-05" type="mesh" contype="0" conaffinity="0" group="1" density="0" rgba="0.7 0.7 0.7 1" mesh="right_shoulder_roll_link"/>
    <geom size="0.03 0.015" pos="-0.00400139 -0.146554 0.235962" quat="1 -3.00026e-05 2.74716e-05 9.57958e-05" type="cylinder" rgba="0.7 0.7 0.7 1"/>
    <geom pos="-4.10007e-06 -0.146797 0.185762" quat="1 -3.00026e-05 2.74716e-05 9.57958e-05" type="mesh" contype="0" conaffinity="0" group="1" density="0" rgba="0.7 0.7 0.7 1" mesh="right_shoulder_yaw_link"/>
    <geom pos="-4.10007e-06 -0.146797 0.185762" quat="1 -3.00026e-05 2.74716e-05 9.57958e-05" type="mesh" rgba="0.7 0.7 0.7 1" mesh="right_shoulder_yaw_link"/>
    <geom pos="0.0157745 -0.146798 0.105243" quat="1 -3.00026e-05 2.74716e-05 9.57958e-05" type="mesh" contype="0" conaffinity="0" group="1" density="0" rgba="0.7 0.7 0.7 1" mesh="right_elbow_link"/>
    <geom pos="0.0157745 -0.146798 0.105243" quat="1 -3.00026e-05 2.74716e-05 9.57958e-05" type="mesh" rgba="0.7 0.7 0.7 1" mesh="right_elbow_link"/>
    <geom pos="0.115774 -0.148668 0.0952374" quat="1 -3.00026e-05 2.74716e-05 9.57958e-05" type="mesh" contype="0" conaffinity="0" group="1" density="0" rgba="0.7 0.7 0.7 1" mesh="right_wrist_roll_rubber_hand"/>
    <geom pos="0.115774 -0.148668 0.0952374" quat="1 -3.00026e-05 2.74716e-05 9.57958e-05" type="mesh" rgba="0.7 0.7 0.7 1" mesh="right_wrist_roll_rubber_hand"/>
    <body name="left_hip_pitch_link" pos="0 0.064452 -0.0985829">
      <inertial pos="0.002741 0.047791 -0.02606" quat="0.954862 0.293964 0.0302556 0.030122" mass="1.77664" diaginertia="0.0023899 0.00202017 0.00153047"/>
      <joint name="left_hip_pitch_joint" pos="0 0 0" axis="0 1 0" range="-2.73774 3.08684" actuatorfrcrange="-98.82 98.82" damping="0.000970688"/>
      <geom type="mesh" contype="0" conaffinity="0" group="1" density="0" rgba="0.2 0.2 0.2 1" mesh="left_hip_pitch_link"/>
      <geom type="mesh" rgba="0.2 0.2 0.2 1" mesh="left_hip_pitch_link"/>
      <body name="left_hip_roll_link" pos="0 0.052 -0.0292437" quat="0.996179 0 -0.0873386 0">
        <inertial pos="0.029812 -0.001045 -0.087934" quat="0.977808 -1.97119e-05 0.205576 -0.0403793" mass="2.00036" diaginertia="0.00335661 0.00317478 0.00195858"/>
        <joint name="left_hip_roll_joint" pos="0 0 0" axis="1 0 0" range="-0.69625 3.13975" actuatorfrcrange="-124 124" damping="0.00122186"/>
        <geom type="mesh" contype="0" conaffinity="0" group="1" density="0" rgba="0.7 0.7 0.7 1" mesh="left_hip_roll_link"/>
        <geom type="mesh" rgba="0.7 0.7 0.7 1" mesh="left_hip_roll_link"/>
        <body name="left_hip_yaw_link" pos="0.025001 0 -0.119144">
          <inertial pos="-0.057709 -0.010981 -0.15078" quat="0.600598 0.15832 0.223482 0.751181" mass="2.23988" diaginertia="0.0102157 0.00944467 0.00210867"/>
          <joint name="left_hip_yaw_joint" pos="0 0 0" axis="0 0 1" range="-2.73504 2.73504" actuatorfrcrange="-101.6 101.6" damping="0.000923594"/>
          <geom type="mesh" contype="0" conaffinity="0" group="1" density="0" rgba="0.7 0.7 0.7 1" mesh="left_hip_yaw_link"/>
          <geom type="mesh" rgba="0.7 0.7 0.7 1" mesh="left_hip_yaw_link"/>
          <body name="left_knee_link" pos="-0.078273 0.0021489 -0.170231" quat="0.996179 0 0.0873386 0">
            <inertial pos="0.005457 0.003964 -0.12074" quat="0.923418 -0.0327699 0.0158246 0.382067" mass="2.54256" diaginertia="0.0149781 0.014843 0.00192853"/>
            <joint name="left_knee_joint" pos="0 0 0" axis="0 1 0" range="-0.123832 2.91636" actuatorfrcrange="-112.7 112.7" damping="0.000951155"/>
            <geom type="mesh" contype="0" conaffinity="0" group="1" density="0" rgba="0.7 0.7 0.7 1" mesh="left_knee_link"/>
            <geom type="mesh" rgba="0.7 0.7 0.7 1" mesh="left_knee_link"/>
            <body name="left_ankle_pitch_link" pos="0 -9.4445e-05 -0.287983">
              <inertial pos="-0.007269 0 0.011137" quat="0.92388 0 0.382683 0" mass="0.097386" diaginertia="0.0131651 0.0131613 0.0131575"/>
              <joint name="left_ankle_pitch_joint" pos="0 0 0" axis="0 1 0" range="-0.851073 0.502003" actuatorfrcrange="-48.29 48.29" damping="0.000938181"/>
              <geom type="mesh" contype="0" conaffinity="0" group="1" density="0" rgba="0.7 0.7 0.7 1" mesh="left_ankle_pitch_link"/>
              <geom type="mesh" rgba="0.7 0.7 0.7 1" mesh="left_ankle_pitch_link"/>
              <body name="left_ankle_roll_link" pos="0 0 -0.0168541">
                <inertial pos="0.026505 0 -0.016425" quat="0.00125164 0.923879 -8.89481e-05 0.382683" mass="0.800145" diaginertia="0.0132785 0.0131612 0.013044"/>
                <joint name="left_ankle_roll_joint" pos="0 0 0" axis="1 0 0" range="-0.27635 0.27635" actuatorfrcrange="-52.76 52.76" damping="0.00119284"/>
                <geom type="mesh" contype="0" conaffinity="0" group="1" density="0" rgba="0.2 0.2 0.2 1" mesh="left_ankle_roll_link"/>
                <geom size="0.005" pos="-0.05 0.025 -0.03" rgba="0.2 0.2 0.2 1"/>
                <geom size="0.005" pos="-0.05 -0.025 -0.03" rgba="0.2 0.2 0.2 1"/>
                <geom size="0.005" pos="0.12 0.03 -0.03" rgba="0.2 0.2 0.2 1"/>
                <geom size="0.005" pos="0.12 -0.03 -0.03" rgba="0.2 0.2 0.2 1"/>
              </body>
            </body>
          </body>
        </body>
      </body>
    </body>
    <body name="right_hip_pitch_link" pos="0 -0.064452 -0.0885651">
      <inertial pos="0.002741 -0.047791 -0.02606" quat="0.954862 -0.293964 0.0302556 -0.030122" mass="1.33234" diaginertia="0.00179259 0.00151532 0.00114809"/>
      <joint name="right_hip_pitch_joint" pos="0 0 0" axis="0 1 0" range="-2.39525 2.74435" actuatorfrcrange="-105 105" damping="0.00102741"/>
      <geom type="mesh" contype="0" conaffinity="0" group="1" density="0" rgba="0.2 0.2 0.2 1" mesh="right_hip_pitch_link"/>
      <geom type="mesh" rgba="0.2 0.2 0.2 1" mesh="right_hip_pitch_link"/>
      <body name="right_hip_roll_link" pos="0 -0.052 -0.026272" quat="0.996179 0 -0.0873386 0">
        <inertial pos="0.029812 0.001045 -0.087934" quat="0.977808 1.97119e-05 0.205576 0.0403793" mass="1.50011" diaginertia="0.00251734 0.00238098 0.00146893"/>
        <joint name="right_hip_roll_joint" pos="0 0 0" axis="1 0 0" range="-3.04231 0.59881" actuatorfrcrange="-131.4 131.4" damping="0.000926592"/>
        <geom type="mesh" contype="0" conaffinity="0" group="1" density="0" rgba="0.7 0.7 0.7 1" mesh="right_hip_roll_link"/>
        <geom type="mesh" rgba="0.7 0.7 0.7 1" mesh="right_hip_roll_link"/>
        <body name="right_hip_yaw_link" pos="0.025001 0 -0.107037">
          <inertial pos="-0.057709 0.010981 -0.15078" quat="0.751181 0.223482 0.15832 0.600598" mass="1.67973" diaginertia="0.00766097 0.00708272 0.00158131"/>
          <joint name="right_hip_yaw_joint" pos="0 0 0" axis="0 0 1" range="-2.51715 2.51715" actuatorfrcrange="-97.58 97.58" damping="0.00125149"/>
          <geom type="mesh" contype="0" conaffinity="0" group="1" density="0" rgba="0.7 0.7 0.7 1" mesh="right_hip_yaw_link"/>
          <geom type="mesh" rgba="0.7 0.7 0.7 1" mesh="right_hip_yaw_link"/>
          <body name="right_knee_link" pos="-0.078273 -0.0021489 -0.152932" quat="0.996179 0 0.0873386 0">
            <inertial pos="0.005457 -0.003964 -0.12074" quat="0.923439 0.0345276 0.0116333 -0.382012" mass="1.90672" diaginertia="0.0112263 0.0111378 0.00144652"/>
            <joint name="right_knee_joint" pos="0 0 0" axis="0 1 0" range="-0.00757767 2.80011" actuatorfrcrange="-121.6 121.6" damping="0.000860126"/>
            <geom type="mesh" contype="0" conaffinity="0" group="1" density="0" rgba="0.7 0.7 0.7 1" mesh="right_knee_link"/>
            <geom type="mesh" rgba="0.7 0.7 0.7 1" mesh="right_knee_link"/>
            <body name="right_ankle_pitch_link" pos="0 9.4445e-05 -0.258719">
              <inertial pos="-0.007269 0 0.011137" quat="0.92388 0 0.382683 0" mass="0.0730317" diaginertia="0.00987292 0.00987006 0.0098672"/>
              <joint name="right_ankle_pitch_joint" pos="0 0 0" axis="0 1 0" range="-0.883601 0.534531" actuatorfrcrange="-47.09 47.09" damping="0.00112176"/>
              <geom type="mesh" contype="0" conaffinity="0" group="1" density="0" rgba="0.7 0.7 0.7 1" mesh="right_ankle_pitch_link"/>
              <geom type="mesh" rgba="0.7 0.7 0.7 1" mesh="right_ankle_pitch_link"/>
              <body name="right_ankle_roll_link" pos="0 0 -0.0151414">
                <inertial pos="0.026505 0 -0.016425" quat="-0.00125164 0.923879 8.89481e-05 0.382683" mass="0.600045" diaginertia="0.00995811 0.00987017 0.00978224"/>
                <joint name="right_ankle_roll_joint" pos="0 0 0" axis="1 0 0" range="-0.269926 0.269926" actuatorfrcrange="-55.43 55.43" damping="0.0011604"/>
                <geom type="mesh" contype="0" conaffinity="0" group="1" density="0" rgba="0.2 0.2 0.2 1" mesh="right_ankle_roll_link"/>
                <geom size="0.005" pos="-0.05 0.025 -0.03" rgba="0.2 0.2 0.2 1"/>
                <geom size="0.005" pos="-0.05 -0.025 -0.03" rgba="0.2 0.2 0.2 1"/>
                <geom size="0.005" pos="0.12 0.03 -0.03" rgba="0.2 0.2 0.2 1"/>
                <geom size="0.005" pos="0.12 -0.03 -0.03" rgba="0.2 0.2 0.2 1"/>
              </body>
            </body>
          </body>
        </body>
      </body>
    </body>
  </worldbody>
</mujoco>
