<?xml version='1.0' encoding='UTF-8'?>
<robot name="g1_12dof">
  <mujoco>
    <compiler meshdir="meshes" discardvisual="false" />
  </mujoco>
  <link name="pelvis">
    <inertial>
      <origin xyz="0.0144905 0.000151462 0.144068" rpy="0 0 0" />
      <mass value="16.844893" />
      <inertia ixx="0.52467688" ixy="7.0062409e-05" ixz="0.0099865595" iyy="0.43130368" iyz="-0.00022830761" izz="0.20144343" />
    </inertial>
    <visual>
      <origin xyz="0 0 0" rpy="0 0 0" />
      <geometry>
        <mesh filename="meshes/pelvis.STL" />
      </geometry>
      <material name="dark">
        <color rgba="0.2 0.2 0.2 1" />
      </material>
    </visual>
  </link>
  <link name="pelvis_contour_link">
    <inertial>
      <origin xyz="0 0 0" rpy="0 0 0" />
      <mass value="0.001" />
      <inertia ixx="1e-7" ixy="0" ixz="0" iyy="1e-7" iyz="0" izz="1e-7" />
    </inertial>
    <visual>
      <origin xyz="0 0 0" rpy="0 0 0" />
      <geometry>
        <mesh filename="meshes/pelvis_contour_link.STL" />
      </geometry>
      <material name="white">
        <color rgba="0.7 0.7 0.7 1" />
      </material>
    </visual>
    <collision>
      <origin xyz="0 0 0" rpy="0 0 0" />
      <geometry>
        <mesh filename="meshes/pelvis_contour_link.STL" />
      </geometry>
    </collision>
  </link>
  <joint name="pelvis_contour_joint" type="fixed">
    <parent link="pelvis" />
    <child link="pelvis_contour_link" />
  </joint>
  <link name="left_hip_pitch_link">
    <inertial>
      <origin xyz="0.002741 0.047791 -0.02606" rpy="0 0 0" />
      <mass value="1.2822517" />
      <inertia ixx="0.0017201215" ixy="3.4953312e-05" ixz="-3.2673783e-05" iyy="0.0013480765" iyz="0.00016241878" izz="0.0012169057" />
    </inertial>
    <visual>
      <origin xyz="0 0 0" rpy="0 0 0" />
      <geometry>
        <mesh filename="meshes/left_hip_pitch_link.STL" />
      </geometry>
      <material name="dark">
        <color rgba="0.2 0.2 0.2 1" />
      </material>
    </visual>
    <collision>
      <origin xyz="0 0 0" rpy="0 0 0" />
      <geometry>
        <mesh filename="meshes/left_hip_pitch_link.STL" />
      </geometry>
    </collision>
  </link>
  <joint name="left_hip_pitch_joint" type="revolute">
    <origin xyz="0 0.070261888 -0.11195767" rpy="0 0 0" />
    <parent link="pelvis" />
    <child link="left_hip_pitch_link" />
    <axis xyz="0 1 0" />
    <limit lower="-2.5934602" upper="2.9425602" effort="88" velocity="32" />
  </joint>
  <link name="left_hip_roll_link">
    <inertial>
      <origin xyz="0.029812 -0.001045 -0.087934" rpy="0 0 0" />
      <mass value="1.4437204" />
      <inertia ixx="0.0022579979" ixy="-3.6094575e-06" ixz="-0.00037118826" iyy="0.0022912396" iyz="1.7476704e-05" izz="0.0015762215" />
    </inertial>
    <visual>
      <origin xyz="0 0 0" rpy="0 0 0" />
      <geometry>
        <mesh filename="meshes/left_hip_roll_link.STL" />
      </geometry>
      <material name="white">
        <color rgba="0.7 0.7 0.7 1" />
      </material>
    </visual>
    <collision>
      <origin xyz="0 0 0" rpy="0 0 0" />
      <geometry>
        <mesh filename="meshes/left_hip_roll_link.STL" />
      </geometry>
    </collision>
  </link>
  <joint name="left_hip_roll_joint" type="revolute">
    <origin xyz="0 0.052 -0.030465" rpy="0 -0.1749001 0" />
    <parent link="left_hip_pitch_link" />
    <child link="left_hip_roll_link" />
    <axis xyz="1 0 0" />
    <limit lower="-0.56409106" upper="3.0075911" effort="139" velocity="20" />
  </joint>
  <link name="left_hip_yaw_link">
    <inertial>
      <origin xyz="-0.057709 -0.010981 -0.15078" rpy="0 0 0" />
      <mass value="1.6165869" />
      <inertia ixx="0.0054874685" ixy="-0.00051394727" ixz="-0.0022746245" iyy="0.0072303857" iyz="-0.00067171348" izz="0.0029909731" />
    </inertial>
    <visual>
      <origin xyz="0 0 0" rpy="0 0 0" />
      <geometry>
        <mesh filename="meshes/left_hip_yaw_link.STL" />
      </geometry>
      <material name="white">
        <color rgba="0.7 0.7 0.7 1" />
      </material>
    </visual>
    <collision>
      <origin xyz="0 0 0" rpy="0 0 0" />
      <geometry>
        <mesh filename="meshes/left_hip_yaw_link.STL" />
      </geometry>
    </collision>
  </link>
  <joint name="left_hip_yaw_joint" type="revolute">
    <origin xyz="0.025001 0 -0.12412" rpy="0 0 0" />
    <parent link="left_hip_roll_link" />
    <child link="left_hip_yaw_link" />
    <axis xyz="0 0 1" />
    <limit lower="-2.8215746" upper="2.8215746" effort="88" velocity="32" />
  </joint>
  <link name="left_knee_link">
    <inertial>
      <origin xyz="0.005457 0.003964 -0.12074" rpy="0 0 0" />
      <mass value="1.8350446" />
      <inertia ixx="0.01076046" ixy="4.5749333e-05" ixz="-4.2644182e-05" iyy="0.01071107" iyz="-0.00067873905" izz="0.0014406765" />
    </inertial>
    <visual>
      <origin xyz="0 0 0" rpy="0 0 0" />
      <geometry>
        <mesh filename="meshes/left_knee_link.STL" />
      </geometry>
      <material name="white">
        <color rgba="0.7 0.7 0.7 1" />
      </material>
    </visual>
    <collision>
      <origin xyz="0 0 0" rpy="0 0 0" />
      <geometry>
        <mesh filename="meshes/left_knee_link.STL" />
      </geometry>
    </collision>
  </link>
  <joint name="left_knee_joint" type="revolute">
    <origin xyz="-0.085328752 0.002342608 -0.19332594" rpy="0 0.1749001 0" />
    <parent link="left_hip_yaw_link" />
    <child link="left_knee_link" />
    <axis xyz="0 1 0" />
    <limit lower="-0.12168408" upper="2.9142171" effort="139" velocity="20" />
  </joint>
  <link name="left_ankle_pitch_link">
    <inertial>
      <origin xyz="-0.007269 0 0.011137" rpy="0 0 0" />
      <mass value="0.070286388" />
      <inertia ixx="7.9784528e-06" ixy="-5.088659e-13" ixz="-2.7544618e-06" iyy="1.7951525e-05" iyz="-5.1061947e-13" izz="1.1967686e-05" />
    </inertial>
    <visual>
      <origin xyz="0 0 0" rpy="0 0 0" />
      <geometry>
        <mesh filename="meshes/left_ankle_pitch_link.STL" />
      </geometry>
      <material name="white">
        <color rgba="0.7 0.7 0.7 1" />
      </material>
    </visual>
    <collision>
      <origin xyz="0 0 0" rpy="0 0 0" />
      <geometry>
        <mesh filename="meshes/left_ankle_pitch_link.STL" />
      </geometry>
    </collision>
  </link>
  <joint name="left_ankle_pitch_joint" type="revolute">
    <origin xyz="0 -0.00010295854 -0.32705376" rpy="0 0 0" />
    <parent link="left_knee_link" />
    <child link="left_ankle_pitch_link" />
    <axis xyz="0 1 0" />
    <limit lower="-0.88886631" upper="0.53979631" effort="50" velocity="37" />
  </joint>
  <link name="left_ankle_roll_link">
    <inertial>
      <origin xyz="0.026505 0 -0.016425" rpy="0 0 0" />
      <mass value="0.57748816" />
      <inertia ixx="0.00021190381" ixy="1.8996536e-07" ixz="8.4628446e-05" iyy="0.0015350021" iyz="-9.4981983e-08" izz="0.0015830618" />
    </inertial>
    <visual>
      <origin xyz="0 0 0" rpy="0 0 0" />
      <geometry>
        <mesh filename="meshes/left_ankle_roll_link.STL" />
      </geometry>
      <material name="dark">
        <color rgba="0.2 0.2 0.2 1" />
      </material>
    </visual>
    <collision>
      <origin xyz="-0.05 0.025 -0.03" rpy="0 0 0" />
      <geometry>
        <sphere radius="0.005" />
      </geometry>
    </collision>
    <collision>
      <origin xyz="-0.05 -0.025 -0.03" rpy="0 0 0" />
      <geometry>
        <sphere radius="0.005" />
      </geometry>
    </collision>
    <collision>
      <origin xyz="0.12 0.03 -0.03" rpy="0 0 0" />
      <geometry>
        <sphere radius="0.005" />
      </geometry>
    </collision>
    <collision>
      <origin xyz="0.12 -0.03 -0.03" rpy="0 0 0" />
      <geometry>
        <sphere radius="0.005" />
      </geometry>
    </collision>
  </link>
  <joint name="left_ankle_roll_joint" type="revolute">
    <origin xyz="0 0 -0.017558" rpy="0 0 0" />
    <parent link="left_ankle_pitch_link" />
    <child link="left_ankle_roll_link" />
    <axis xyz="1 0 0" />
    <limit lower="-0.2678736" upper="0.2678736" effort="50" velocity="37" />
  </joint>
  <link name="right_hip_pitch_link">
    <inertial>
      <origin xyz="0.002741 -0.047791 -0.02606" rpy="0 0 0" />
      <mass value="1.2822517" />
      <inertia ixx="0.0017201215" ixy="-3.4953312e-05" ixz="-3.2673783e-05" iyy="0.0013480765" iyz="-0.00016241878" izz="0.0012169057" />
    </inertial>
    <visual>
      <origin xyz="0 0 0" rpy="0 0 0" />
      <geometry>
        <mesh filename="meshes/right_hip_pitch_link.STL" />
      </geometry>
      <material name="dark">
        <color rgba="0.2 0.2 0.2 1" />
      </material>
    </visual>
    <collision>
      <origin xyz="0 0 0" rpy="0 0 0" />
      <geometry>
        <mesh filename="meshes/right_hip_pitch_link.STL" />
      </geometry>
    </collision>
  </link>
  <joint name="right_hip_pitch_joint" type="revolute">
    <origin xyz="0 -0.070261888 -0.11195767" rpy="0 0 0" />
    <parent link="pelvis" />
    <child link="right_hip_pitch_link" />
    <axis xyz="0 1 0" />
    <limit lower="-2.5934602" upper="2.9425602" effort="88" velocity="32" />
  </joint>
  <link name="right_hip_roll_link">
    <inertial>
      <origin xyz="0.029812 0.001045 -0.087934" rpy="0 0 0" />
      <mass value="1.4437204" />
      <inertia ixx="0.0022579979" ixy="3.6094575e-06" ixz="-0.00037118826" iyy="0.0022912396" iyz="-1.7476704e-05" izz="0.0015762215" />
    </inertial>
    <visual>
      <origin xyz="0 0 0" rpy="0 0 0" />
      <geometry>
        <mesh filename="meshes/right_hip_roll_link.STL" />
      </geometry>
      <material name="white">
        <color rgba="0.7 0.7 0.7 1" />
      </material>
    </visual>
    <collision>
      <origin xyz="0 0 0" rpy="0 0 0" />
      <geometry>
        <mesh filename="meshes/right_hip_roll_link.STL" />
      </geometry>
    </collision>
  </link>
  <joint name="right_hip_roll_joint" type="revolute">
    <origin xyz="0 -0.052 -0.030465" rpy="0 -0.1749001 0" />
    <parent link="right_hip_pitch_link" />
    <child link="right_hip_roll_link" />
    <axis xyz="1 0 0" />
    <limit lower="-3.0075911" upper="0.56409106" effort="139" velocity="20" />
  </joint>
  <link name="right_hip_yaw_link">
    <inertial>
      <origin xyz="-0.057709 0.010981 -0.15078" rpy="0 0 0" />
      <mass value="1.6165869" />
      <inertia ixx="0.0054874666" ixy="0.00051394643" ixz="-0.0022746246" iyy="0.0072303844" iyz="0.00067171148" izz="0.0029909731" />
    </inertial>
    <visual>
      <origin xyz="0 0 0" rpy="0 0 0" />
      <geometry>
        <mesh filename="meshes/right_hip_yaw_link.STL" />
      </geometry>
      <material name="white">
        <color rgba="0.7 0.7 0.7 1" />
      </material>
    </visual>
    <collision>
      <origin xyz="0 0 0" rpy="0 0 0" />
      <geometry>
        <mesh filename="meshes/right_hip_yaw_link.STL" />
      </geometry>
    </collision>
  </link>
  <joint name="right_hip_yaw_joint" type="revolute">
    <origin xyz="0.025001 0 -0.12412" rpy="0 0 0" />
    <parent link="right_hip_roll_link" />
    <child link="right_hip_yaw_link" />
    <axis xyz="0 0 1" />
    <limit lower="-2.8215746" upper="2.8215746" effort="88" velocity="32" />
  </joint>
  <link name="right_knee_link">
    <inertial>
      <origin xyz="0.005457 -0.003964 -0.12074" rpy="0 0 0" />
      <mass value="1.8350446" />
      <inertia ixx="0.010760478" ixy="-4.5818162e-05" ixz="4.2644368e-05" iyy="0.010711087" iyz="0.00067873975" izz="0.0014406799" />
    </inertial>
    <visual>
      <origin xyz="0 0 0" rpy="0 0 0" />
      <geometry>
        <mesh filename="meshes/right_knee_link.STL" />
      </geometry>
      <material name="white">
        <color rgba="0.7 0.7 0.7 1" />
      </material>
    </visual>
    <collision>
      <origin xyz="0 0 0" rpy="0 0 0" />
      <geometry>
        <mesh filename="meshes/right_knee_link.STL" />
      </geometry>
    </collision>
  </link>
  <joint name="right_knee_joint" type="revolute">
    <origin xyz="-0.085328752 -0.002342608 -0.19332594" rpy="0 0.1749001 0" />
    <parent link="right_hip_yaw_link" />
    <child link="right_knee_link" />
    <axis xyz="0 1 0" />
    <limit lower="-0.12168408" upper="2.9142171" effort="139" velocity="20" />
  </joint>
  <link name="right_ankle_pitch_link">
    <inertial>
      <origin xyz="-0.007269 0 0.011137" rpy="0 0 0" />
      <mass value="0.070286388" />
      <inertia ixx="7.9784528e-06" ixy="-5.088659e-13" ixz="-2.7544618e-06" iyy="1.7951525e-05" iyz="-5.1061947e-13" izz="1.1967686e-05" />
    </inertial>
    <visual>
      <origin xyz="0 0 0" rpy="0 0 0" />
      <geometry>
        <mesh filename="meshes/right_ankle_pitch_link.STL" />
      </geometry>
      <material name="white">
        <color rgba="0.7 0.7 0.7 1" />
      </material>
    </visual>
    <collision>
      <origin xyz="0 0 0" rpy="0 0 0" />
      <geometry>
        <mesh filename="meshes/right_ankle_pitch_link.STL" />
      </geometry>
    </collision>
  </link>
  <joint name="right_ankle_pitch_joint" type="revolute">
    <origin xyz="0 0.00010295854 -0.32705376" rpy="0 0 0" />
    <parent link="right_knee_link" />
    <child link="right_ankle_pitch_link" />
    <axis xyz="0 1 0" />
    <limit lower="-0.88886631" upper="0.53979631" effort="50" velocity="37" />
  </joint>
  <link name="right_ankle_roll_link">
    <inertial>
      <origin xyz="0.026505 0 -0.016425" rpy="0 0 0" />
      <mass value="0.57748816" />
      <inertia ixx="0.00021190381" ixy="-1.8996536e-07" ixz="8.4628446e-05" iyy="0.0015350021" iyz="9.4981983e-08" izz="0.0015830618" />
    </inertial>
    <visual>
      <origin xyz="0 0 0" rpy="0 0 0" />
      <geometry>
        <mesh filename="meshes/right_ankle_roll_link.STL" />
      </geometry>
      <material name="dark">
        <color rgba="0.2 0.2 0.2 1" />
      </material>
    </visual>
    <collision>
      <origin xyz="-0.05 0.025 -0.03" rpy="0 0 0" />
      <geometry>
        <sphere radius="0.005" />
      </geometry>
    </collision>
    <collision>
      <origin xyz="-0.05 -0.025 -0.03" rpy="0 0 0" />
      <geometry>
        <sphere radius="0.005" />
      </geometry>
    </collision>
    <collision>
      <origin xyz="0.12 0.03 -0.03" rpy="0 0 0" />
      <geometry>
        <sphere radius="0.005" />
      </geometry>
    </collision>
    <collision>
      <origin xyz="0.12 -0.03 -0.03" rpy="0 0 0" />
      <geometry>
        <sphere radius="0.005" />
      </geometry>
    </collision>
  </link>
  <joint name="right_ankle_roll_joint" type="revolute">
    <origin xyz="0 0 -0.017558" rpy="0 0 0" />
    <parent link="right_ankle_pitch_link" />
    <child link="right_ankle_roll_link" />
    <axis xyz="1 0 0" />
    <limit lower="-0.2678736" upper="0.2678736" effort="50" velocity="37" />
  </joint>
  <joint name="waist_yaw_joint" type="fixed">
    <origin xyz="-0.0039635 0 0.044" rpy="0 0 0" />
    <parent link="pelvis" />
    <child link="torso_link" />
    <axis xyz="0 0 1" />
    <limit lower="-2.618" upper="2.618" effort="88" velocity="32" />
  </joint>
  <link name="torso_link">
    <inertial>
      <origin xyz="0.000931 0.000346 0.15082" rpy="0 0 0" />
      <mass value="6.78" />
      <inertia ixx="0.05905" ixy="3.3302E-05" ixz="-0.0017715" iyy="0.047014" iyz="-2.2399E-05" izz="0.025652" />
    </inertial>
    <visual>
      <origin xyz="0.0039635 0 -0.044" rpy="0 0 0" />
      <geometry>
        <mesh filename="meshes/torso_link_23dof_rev_1_0.STL" />
      </geometry>
      <material name="white">
        <color rgba="0.7 0.7 0.7 1" />
      </material>
    </visual>
    <collision>
      <origin xyz="0.0039635 0 -0.044" rpy="0 0 0" />
      <geometry>
        <mesh filename="meshes/torso_link_23dof_rev_1_0.STL" />
      </geometry>
    </collision>
  </link>
  <joint name="logo_joint" type="fixed">
    <origin xyz="0.0039635 0 -0.044" rpy="0 0 0" />
    <parent link="torso_link" />
    <child link="logo_link" />
  </joint>
  <link name="logo_link">
    <inertial>
      <origin xyz="0 0 0" rpy="0 0 0" />
      <mass value="0.001" />
      <inertia ixx="1e-7" ixy="0" ixz="0" iyy="1e-7" iyz="0" izz="1e-7" />
    </inertial>
    <visual>
      <origin xyz="0 0 0" rpy="0 0 0" />
      <geometry>
        <mesh filename="meshes/logo_link.STL" />
      </geometry>
      <material name="dark">
        <color rgba="0.2 0.2 0.2 1" />
      </material>
    </visual>
    <collision>
      <origin xyz="0 0 0" rpy="0 0 0" />
      <geometry>
        <mesh filename="meshes/logo_link.STL" />
      </geometry>
    </collision>
  </link>
  <link name="head_link">
    <inertial>
      <origin xyz="0.005267 0.000299 0.449869" rpy="0 0 0" />
      <mass value="1.036" />
      <inertia ixx="0.004085051" ixy="-2.543E-06" ixz="-6.9455E-05" iyy="0.004185212" iyz="-3.726E-06" izz="0.001807911" />
    </inertial>
    <visual>
      <origin xyz="0 0 0" rpy="0 0 0" />
      <geometry>
        <mesh filename="meshes/head_link.STL" />
      </geometry>
      <material name="dark">
        <color rgba="0.2 0.2 0.2 1" />
      </material>
    </visual>
    <collision>
      <origin xyz="0 0 0" rpy="0 0 0" />
      <geometry>
        <mesh filename="meshes/head_link.STL" />
      </geometry>
    </collision>
  </link>
  <joint name="head_joint" type="fixed">
    <origin xyz="0.0039635 0 -0.044" rpy="0 0 0" />
    <parent link="torso_link" />
    <child link="head_link" />
  </joint>
  <link name="imu_in_torso" />
  <joint name="imu_in_torso_joint" type="fixed">
    <origin xyz="-0.03959 -0.00224 0.14792" rpy="0 0 0" />
    <parent link="torso_link" />
    <child link="imu_in_torso" />
  </joint>
  <link name="imu_in_pelvis" />
  <joint name="imu_in_pelvis_joint" type="fixed">
    <origin xyz="0.04525 0 -0.08339" rpy="0 0 0" />
    <parent link="pelvis" />
    <child link="imu_in_pelvis" />
  </joint>
  <link name="d435_link" />
  <joint name="d435_joint" type="fixed">
    <origin xyz="0.0576235 0.01753 0.42987" rpy="0 0.8307767239493009 0" />
    <parent link="torso_link" />
    <child link="d435_link" />
  </joint>
  <link name="mid360_link" />
  <joint name="mid360_joint" type="fixed">
    <origin xyz="0.0002835 0.00003 0.41618" rpy="0 0.04014257279586953 0" />
    <parent link="torso_link" />
    <child link="mid360_link" />
  </joint>
  <link name="left_shoulder_pitch_link">
    <inertial>
      <origin xyz="0 0.035892 -0.011628" rpy="0 0 0" />
      <mass value="0.718" />
      <inertia ixx="0.0004291" ixy="-9.2E-06" ixz="6.4E-06" iyy="0.000453" iyz="2.26E-05" izz="0.000423" />
    </inertial>
    <visual>
      <origin xyz="0 0 0" rpy="0 0 0" />
      <geometry>
        <mesh filename="meshes/left_shoulder_pitch_link.STL" />
      </geometry>
      <material name="white">
        <color rgba="0.7 0.7 0.7 1" />
      </material>
    </visual>
    <collision>
      <origin xyz="0 0.04 -0.01" rpy="0 1.5707963267948966 0" />
      <geometry>
        <cylinder radius="0.03" length="0.05" />
      </geometry>
    </collision>
  </link>
  <joint name="left_shoulder_pitch_joint" type="fixed">
    <origin xyz="0.0039563 0.10022 0.24778" rpy="0.27931 5.4949E-05 -0.00019159" />
    <parent link="torso_link" />
    <child link="left_shoulder_pitch_link" />
    <axis xyz="0 1 0" />
    <limit lower="-3.0892" upper="2.6704" effort="25" velocity="37" />
  </joint>
  <link name="left_shoulder_roll_link">
    <inertial>
      <origin xyz="-0.000227 0.00727 -0.063243" rpy="0 0 0" />
      <mass value="0.643" />
      <inertia ixx="0.0006177" ixy="-1E-06" ixz="8.7E-06" iyy="0.0006912" iyz="-5.3E-06" izz="0.0003894" />
    </inertial>
    <visual>
      <origin xyz="0 0 0" rpy="0 0 0" />
      <geometry>
        <mesh filename="meshes/left_shoulder_roll_link.STL" />
      </geometry>
      <material name="white">
        <color rgba="0.7 0.7 0.7 1" />
      </material>
    </visual>
    <collision>
      <origin xyz="-0.004 0.006 -0.053" rpy="0 0 0" />
      <geometry>
        <cylinder radius="0.03" length="0.03" />
      </geometry>
    </collision>
  </link>
  <joint name="left_shoulder_roll_joint" type="fixed">
    <origin xyz="0 0.038 -0.013831" rpy="-0.27925 0 0" />
    <parent link="left_shoulder_pitch_link" />
    <child link="left_shoulder_roll_link" />
    <axis xyz="1 0 0" />
    <limit lower="-1.5882" upper="2.2515" effort="25" velocity="37" />
  </joint>
  <link name="left_shoulder_yaw_link">
    <inertial>
      <origin xyz="0.010773 -0.002949 -0.072009" rpy="0 0 0" />
      <mass value="0.734" />
      <inertia ixx="0.0009988" ixy="7.9E-06" ixz="0.0001412" iyy="0.0010605" iyz="-2.86E-05" izz="0.0004354" />
    </inertial>
    <visual>
      <origin xyz="0 0 0" rpy="0 0 0" />
      <geometry>
        <mesh filename="meshes/left_shoulder_yaw_link.STL" />
      </geometry>
      <material name="white">
        <color rgba="0.7 0.7 0.7 1" />
      </material>
    </visual>
    <collision>
      <origin xyz="0 0 0" rpy="0 0 0" />
      <geometry>
        <mesh filename="meshes/left_shoulder_yaw_link.STL" />
      </geometry>
    </collision>
  </link>
  <joint name="left_shoulder_yaw_joint" type="fixed">
    <origin xyz="0 0.00624 -0.1032" rpy="0 0 0" />
    <parent link="left_shoulder_roll_link" />
    <child link="left_shoulder_yaw_link" />
    <axis xyz="0 0 1" />
    <limit lower="-2.618" upper="2.618" effort="25" velocity="37" />
  </joint>
  <link name="left_elbow_link">
    <inertial>
      <origin xyz="0.064956 0.004454 -0.010062" rpy="0 0 0" />
      <mass value="0.6" />
      <inertia ixx="0.0002891" ixy="6.53E-05" ixz="1.72E-05" iyy="0.0004152" iyz="-5.6E-06" izz="0.0004197" />
    </inertial>
    <visual>
      <origin xyz="0 0 0" rpy="0 0 0" />
      <geometry>
        <mesh filename="meshes/left_elbow_link.STL" />
      </geometry>
      <material name="white">
        <color rgba="0.7 0.7 0.7 1" />
      </material>
    </visual>
    <collision>
      <origin xyz="0 0 0" rpy="0 0 0" />
      <geometry>
        <mesh filename="meshes/left_elbow_link.STL" />
      </geometry>
    </collision>
  </link>
  <joint name="left_elbow_joint" type="fixed">
    <origin xyz="0.015783 0 -0.080518" rpy="0 0 0" />
    <parent link="left_shoulder_yaw_link" />
    <child link="left_elbow_link" />
    <axis xyz="0 1 0" />
    <limit lower="-1.0472" upper="2.0944" effort="25" velocity="37" />
  </joint>
  <joint name="left_wrist_roll_joint" type="fixed">
    <origin xyz="0.100 0.00188791 -0.010" rpy="0 0 0" />
    <axis xyz="1 0 0" />
    <parent link="left_elbow_link" />
    <child link="left_wrist_roll_rubber_hand" />
    <limit effort="25" velocity="37" lower="-1.972222054" upper="1.972222054" />
  </joint>
  <link name="left_wrist_roll_rubber_hand">
    <inertial>
      <origin xyz="0.10794656650 0.00163511945 0.00202244863" rpy="0 0 0" />
      <mass value="0.35692864" />
      <inertia ixx="0.00019613494735" ixy="-0.00000419816908" ixz="-0.00003950860580" iyy="0.00200280358206" iyz="0.00000249774203" izz="0.00194181412808" />
    </inertial>
    <visual>
      <origin xyz="0 0 0" rpy="0 0 0" />
      <geometry>
        <mesh filename="meshes/left_wrist_roll_rubber_hand.STL" />
      </geometry>
      <material name="white">
        <color rgba="0.7 0.7 0.7 1" />
      </material>
    </visual>
    <collision>
      <origin xyz="0 0 0" rpy="0 0 0" />
      <geometry>
        <mesh filename="meshes/left_wrist_roll_rubber_hand.STL" />
      </geometry>
    </collision>
  </link>
  <link name="right_shoulder_pitch_link">
    <inertial>
      <origin xyz="0 -0.035892 -0.011628" rpy="0 0 0" />
      <mass value="0.718" />
      <inertia ixx="0.0004291" ixy="9.2E-06" ixz="6.4E-06" iyy="0.000453" iyz="-2.26E-05" izz="0.000423" />
    </inertial>
    <visual>
      <origin xyz="0 0 0" rpy="0 0 0" />
      <geometry>
        <mesh filename="meshes/right_shoulder_pitch_link.STL" />
      </geometry>
      <material name="white">
        <color rgba="0.7 0.7 0.7 1" />
      </material>
    </visual>
    <collision>
      <origin xyz="0 -0.04 -0.01" rpy="0 1.5707963267948966 0" />
      <geometry>
        <cylinder radius="0.03" length="0.05" />
      </geometry>
    </collision>
  </link>
  <joint name="right_shoulder_pitch_joint" type="fixed">
    <origin xyz="0.0039563 -0.10021 0.24778" rpy="-0.27931 5.4949E-05 0.00019159" />
    <parent link="torso_link" />
    <child link="right_shoulder_pitch_link" />
    <axis xyz="0 1 0" />
    <limit lower="-3.0892" upper="2.6704" effort="25" velocity="37" />
  </joint>
  <link name="right_shoulder_roll_link">
    <inertial>
      <origin xyz="-0.000227 -0.00727 -0.063243" rpy="0 0 0" />
      <mass value="0.643" />
      <inertia ixx="0.0006177" ixy="1E-06" ixz="8.7E-06" iyy="0.0006912" iyz="5.3E-06" izz="0.0003894" />
    </inertial>
    <visual>
      <origin xyz="0 0 0" rpy="0 0 0" />
      <geometry>
        <mesh filename="meshes/right_shoulder_roll_link.STL" />
      </geometry>
      <material name="white">
        <color rgba="0.7 0.7 0.7 1" />
      </material>
    </visual>
    <collision>
      <origin xyz="-0.004 -0.006 -0.053" rpy="0 0 0" />
      <geometry>
        <cylinder radius="0.03" length="0.03" />
      </geometry>
    </collision>
  </link>
  <joint name="right_shoulder_roll_joint" type="fixed">
    <origin xyz="0 -0.038 -0.013831" rpy="0.27925 0 0" />
    <parent link="right_shoulder_pitch_link" />
    <child link="right_shoulder_roll_link" />
    <axis xyz="1 0 0" />
    <limit lower="-2.2515" upper="1.5882" effort="25" velocity="37" />
  </joint>
  <link name="right_shoulder_yaw_link">
    <inertial>
      <origin xyz="0.010773 0.002949 -0.072009" rpy="0 0 0" />
      <mass value="0.734" />
      <inertia ixx="0.0009988" ixy="-7.9E-06" ixz="0.0001412" iyy="0.0010605" iyz="2.86E-05" izz="0.0004354" />
    </inertial>
    <visual>
      <origin xyz="0 0 0" rpy="0 0 0" />
      <geometry>
        <mesh filename="meshes/right_shoulder_yaw_link.STL" />
      </geometry>
      <material name="white">
        <color rgba="0.7 0.7 0.7 1" />
      </material>
    </visual>
    <collision>
      <origin xyz="0 0 0" rpy="0 0 0" />
      <geometry>
        <mesh filename="meshes/right_shoulder_yaw_link.STL" />
      </geometry>
    </collision>
  </link>
  <joint name="right_shoulder_yaw_joint" type="fixed">
    <origin xyz="0 -0.00624 -0.1032" rpy="0 0 0" />
    <parent link="right_shoulder_roll_link" />
    <child link="right_shoulder_yaw_link" />
    <axis xyz="0 0 1" />
    <limit lower="-2.618" upper="2.618" effort="25" velocity="37" />
  </joint>
  <link name="right_elbow_link">
    <inertial>
      <origin xyz="0.064956 -0.004454 -0.010062" rpy="0 0 0" />
      <mass value="0.6" />
      <inertia ixx="0.0002891" ixy="-6.53E-05" ixz="1.72E-05" iyy="0.0004152" iyz="5.6E-06" izz="0.0004197" />
    </inertial>
    <visual>
      <origin xyz="0 0 0" rpy="0 0 0" />
      <geometry>
        <mesh filename="meshes/right_elbow_link.STL" />
      </geometry>
      <material name="white">
        <color rgba="0.7 0.7 0.7 1" />
      </material>
    </visual>
    <collision>
      <origin xyz="0 0 0" rpy="0 0 0" />
      <geometry>
        <mesh filename="meshes/right_elbow_link.STL" />
      </geometry>
    </collision>
  </link>
  <joint name="right_elbow_joint" type="fixed">
    <origin xyz="0.015783 0 -0.080518" rpy="0 0 0" />
    <parent link="right_shoulder_yaw_link" />
    <child link="right_elbow_link" />
    <axis xyz="0 1 0" />
    <limit lower="-1.0472" upper="2.0944" effort="25" velocity="37" />
  </joint>
  <joint name="right_wrist_roll_joint" type="fixed">
    <origin xyz="0.100 -0.00188791 -0.010" rpy="0 0 0" />
    <axis xyz="1 0 0" />
    <parent link="right_elbow_link" />
    <child link="right_wrist_roll_rubber_hand" />
    <limit effort="25" velocity="37" lower="-1.972222054" upper="1.972222054" />
  </joint>
  <link name="right_wrist_roll_rubber_hand">
    <inertial>
      <origin xyz="0.10794656650 -0.00163511945 0.00202244863" rpy="0 0 0" />
      <mass value="0.35692864" />
      <inertia ixx="0.00019613494735" ixy="0.00000419816908" ixz="-0.00003950860580" iyy="0.00200280358206" iyz="-0.00000249774203" izz="0.00194181412808" />
    </inertial>
    <visual>
      <origin xyz="0 0 0" rpy="0 0 0" />
      <geometry>
        <mesh filename="meshes/right_wrist_roll_rubber_hand.STL" />
      </geometry>
      <material name="white">
        <color rgba="0.7 0.7 0.7 1" />
      </material>
    </visual>
    <collision>
      <origin xyz="0 0 0" rpy="0 0 0" />
      <geometry>
        <mesh filename="meshes/right_wrist_roll_rubber_hand.STL" />
      </geometry>
    </collision>
  </link>
</robot>
