<?xml version='1.0' encoding='UTF-8'?>
<robot name="g1_12dof">
  <mujoco>
    <compiler meshdir="meshes" discardvisual="false" />
  </mujoco>
  <link name="pelvis">
    <inertial>
      <origin xyz="0.0144905 0.000151462 0.144068" rpy="0 0 0" />
      <mass value="20.093235" />
      <inertia ixx="0.62585474" ixy="8.3573133e-05" ixz="0.011912352" iyy="0.51447559" iyz="-0.00027233408" izz="0.24028945" />
    </inertial>
    <visual>
      <origin xyz="0 0 0" rpy="0 0 0" />
      <geometry>
        <mesh filename="meshes/pelvis.STL" />
      </geometry>
      <material name="dark">
        <color rgba="0.2 0.2 0.2 1" />
      </material>
    </visual>
  </link>
  <link name="pelvis_contour_link">
    <inertial>
      <origin xyz="0 0 0" rpy="0 0 0" />
      <mass value="0.001" />
      <inertia ixx="1e-7" ixy="0" ixz="0" iyy="1e-7" iyz="0" izz="1e-7" />
    </inertial>
    <visual>
      <origin xyz="0 0 0" rpy="0 0 0" />
      <geometry>
        <mesh filename="meshes/pelvis_contour_link.STL" />
      </geometry>
      <material name="white">
        <color rgba="0.7 0.7 0.7 1" />
      </material>
    </visual>
    <collision>
      <origin xyz="0 0 0" rpy="0 0 0" />
      <geometry>
        <mesh filename="meshes/pelvis_contour_link.STL" />
      </geometry>
    </collision>
  </link>
  <joint name="pelvis_contour_joint" type="fixed">
    <parent link="pelvis" />
    <child link="pelvis_contour_link" />
  </joint>
  <link name="left_hip_pitch_link">
    <inertial>
      <origin xyz="0.002741 0.047791 -0.02606" rpy="0 0 0" />
      <mass value="1.529519" />
      <inertia ixx="0.002051827" ixy="4.1693653e-05" ixz="-3.8974543e-05" iyy="0.0016080374" iyz="0.00019373935" izz="0.0014515719" />
    </inertial>
    <visual>
      <origin xyz="0 0 0" rpy="0 0 0" />
      <geometry>
        <mesh filename="meshes/left_hip_pitch_link.STL" />
      </geometry>
      <material name="dark">
        <color rgba="0.2 0.2 0.2 1" />
      </material>
    </visual>
    <collision>
      <origin xyz="0 0 0" rpy="0 0 0" />
      <geometry>
        <mesh filename="meshes/left_hip_pitch_link.STL" />
      </geometry>
    </collision>
  </link>
  <joint name="left_hip_pitch_joint" type="revolute">
    <origin xyz="0 0.060743936 -0.096791445" rpy="0 0 0" />
    <parent link="pelvis" />
    <child link="left_hip_pitch_link" />
    <axis xyz="0 1 0" />
    <limit lower="-2.4446257" upper="2.7937257" effort="88" velocity="32" />
  </joint>
  <link name="left_hip_roll_link">
    <inertial>
      <origin xyz="0.029812 -0.001045 -0.087934" rpy="0 0 0" />
      <mass value="1.7221251" />
      <inertia ixx="0.0026934266" ixy="-4.3054995e-06" ixz="-0.00044276761" iyy="0.0027330786" iyz="2.0846884e-05" izz="0.0018801776" />
    </inertial>
    <visual>
      <origin xyz="0 0 0" rpy="0 0 0" />
      <geometry>
        <mesh filename="meshes/left_hip_roll_link.STL" />
      </geometry>
      <material name="white">
        <color rgba="0.7 0.7 0.7 1" />
      </material>
    </visual>
    <collision>
      <origin xyz="0 0 0" rpy="0 0 0" />
      <geometry>
        <mesh filename="meshes/left_hip_roll_link.STL" />
      </geometry>
    </collision>
  </link>
  <joint name="left_hip_roll_joint" type="revolute">
    <origin xyz="0 0.052 -0.030465" rpy="0 -0.1749001 0" />
    <parent link="left_hip_pitch_link" />
    <child link="left_hip_roll_link" />
    <axis xyz="1 0 0" />
    <limit lower="-0.46806732" upper="2.9115673" effort="139" velocity="20" />
  </joint>
  <link name="left_hip_yaw_link">
    <inertial>
      <origin xyz="-0.057709 -0.010981 -0.15078" rpy="0 0 0" />
      <mass value="1.9283269" />
      <inertia ixx="0.0065456631" ixy="-0.00061305604" ixz="-0.0027132594" iyy="0.0086246818" iyz="-0.00080124564" izz="0.0035677476" />
    </inertial>
    <visual>
      <origin xyz="0 0 0" rpy="0 0 0" />
      <geometry>
        <mesh filename="meshes/left_hip_yaw_link.STL" />
      </geometry>
      <material name="white">
        <color rgba="0.7 0.7 0.7 1" />
      </material>
    </visual>
    <collision>
      <origin xyz="0 0 0" rpy="0 0 0" />
      <geometry>
        <mesh filename="meshes/left_hip_yaw_link.STL" />
      </geometry>
    </collision>
  </link>
  <joint name="left_hip_yaw_joint" type="revolute">
    <origin xyz="0.025001 0 -0.12412" rpy="0 0 0" />
    <parent link="left_hip_roll_link" />
    <child link="left_hip_yaw_link" />
    <axis xyz="0 0 1" />
    <limit lower="-2.6698601" upper="2.6698601" effort="88" velocity="32" />
  </joint>
  <link name="left_knee_link">
    <inertial>
      <origin xyz="0.005457 0.003964 -0.12074" rpy="0 0 0" />
      <mass value="2.1889117" />
      <inertia ixx="0.01283549" ixy="5.4571561e-05" ixz="-5.0867618e-05" iyy="0.012776576" iyz="-0.000809626" izz="0.0017184943" />
    </inertial>
    <visual>
      <origin xyz="0 0 0" rpy="0 0 0" />
      <geometry>
        <mesh filename="meshes/left_knee_link.STL" />
      </geometry>
      <material name="white">
        <color rgba="0.7 0.7 0.7 1" />
      </material>
    </visual>
    <collision>
      <origin xyz="0 0 0" rpy="0 0 0" />
      <geometry>
        <mesh filename="meshes/left_knee_link.STL" />
      </geometry>
    </collision>
  </link>
  <joint name="left_knee_joint" type="revolute">
    <origin xyz="-0.073769784 0.0020252691 -0.16713724" rpy="0 0.1749001 0" />
    <parent link="left_hip_yaw_link" />
    <child link="left_knee_link" />
    <axis xyz="0 1 0" />
    <limit lower="-0.040064668" upper="2.8325977" effort="139" velocity="20" />
  </joint>
  <link name="left_ankle_pitch_link">
    <inertial>
      <origin xyz="-0.007269 0 0.011137" rpy="0 0 0" />
      <mass value="0.083840302" />
      <inertia ixx="9.5170049e-06" ixy="-6.0699478e-13" ixz="-3.2856278e-06" iyy="2.1413268e-05" iyz="-6.0908652e-13" izz="1.4275515e-05" />
    </inertial>
    <visual>
      <origin xyz="0 0 0" rpy="0 0 0" />
      <geometry>
        <mesh filename="meshes/left_ankle_pitch_link.STL" />
      </geometry>
      <material name="white">
        <color rgba="0.7 0.7 0.7 1" />
      </material>
    </visual>
    <collision>
      <origin xyz="0 0 0" rpy="0 0 0" />
      <geometry>
        <mesh filename="meshes/left_ankle_pitch_link.STL" />
      </geometry>
    </collision>
  </link>
  <joint name="left_ankle_pitch_joint" type="revolute">
    <origin xyz="0 -8.9011373e-05 -0.28274977" rpy="0 0 0" />
    <parent link="left_knee_link" />
    <child link="left_ankle_pitch_link" />
    <axis xyz="0 1 0" />
    <limit lower="-0.85045709" upper="0.50138709" effort="50" velocity="37" />
  </joint>
  <link name="left_ankle_roll_link">
    <inertial>
      <origin xyz="0.026505 0 -0.016425" rpy="0 0 0" />
      <mass value="0.68885005" />
      <inertia ixx="0.000252767" ixy="2.2659798e-07" ixz="0.00010094806" iyy="0.0018310094" iyz="-1.1329816e-07" izz="0.0018883369" />
    </inertial>
    <visual>
      <origin xyz="0 0 0" rpy="0 0 0" />
      <geometry>
        <mesh filename="meshes/left_ankle_roll_link.STL" />
      </geometry>
      <material name="dark">
        <color rgba="0.2 0.2 0.2 1" />
      </material>
    </visual>
    <collision>
      <origin xyz="-0.05 0.025 -0.03" rpy="0 0 0" />
      <geometry>
        <sphere radius="0.005" />
      </geometry>
    </collision>
    <collision>
      <origin xyz="-0.05 -0.025 -0.03" rpy="0 0 0" />
      <geometry>
        <sphere radius="0.005" />
      </geometry>
    </collision>
    <collision>
      <origin xyz="0.12 0.03 -0.03" rpy="0 0 0" />
      <geometry>
        <sphere radius="0.005" />
      </geometry>
    </collision>
    <collision>
      <origin xyz="0.12 -0.03 -0.03" rpy="0 0 0" />
      <geometry>
        <sphere radius="0.005" />
      </geometry>
    </collision>
  </link>
  <joint name="left_ankle_roll_joint" type="revolute">
    <origin xyz="0 0 -0.017558" rpy="0 0 0" />
    <parent link="left_ankle_pitch_link" />
    <child link="left_ankle_roll_link" />
    <axis xyz="1 0 0" />
    <limit lower="-0.25347018" upper="0.25347018" effort="50" velocity="37" />
  </joint>
  <link name="right_hip_pitch_link">
    <inertial>
      <origin xyz="0.002741 -0.047791 -0.02606" rpy="0 0 0" />
      <mass value="1.529519" />
      <inertia ixx="0.002051827" ixy="-4.1693653e-05" ixz="-3.8974543e-05" iyy="0.0016080374" iyz="-0.00019373935" izz="0.0014515719" />
    </inertial>
    <visual>
      <origin xyz="0 0 0" rpy="0 0 0" />
      <geometry>
        <mesh filename="meshes/right_hip_pitch_link.STL" />
      </geometry>
      <material name="dark">
        <color rgba="0.2 0.2 0.2 1" />
      </material>
    </visual>
    <collision>
      <origin xyz="0 0 0" rpy="0 0 0" />
      <geometry>
        <mesh filename="meshes/right_hip_pitch_link.STL" />
      </geometry>
    </collision>
  </link>
  <joint name="right_hip_pitch_joint" type="revolute">
    <origin xyz="0 -0.060743936 -0.096791445" rpy="0 0 0" />
    <parent link="pelvis" />
    <child link="right_hip_pitch_link" />
    <axis xyz="0 1 0" />
    <limit lower="-2.4446257" upper="2.7937257" effort="88" velocity="32" />
  </joint>
  <link name="right_hip_roll_link">
    <inertial>
      <origin xyz="0.029812 0.001045 -0.087934" rpy="0 0 0" />
      <mass value="1.7221251" />
      <inertia ixx="0.0026934266" ixy="4.3054995e-06" ixz="-0.00044276761" iyy="0.0027330786" iyz="-2.0846884e-05" izz="0.0018801776" />
    </inertial>
    <visual>
      <origin xyz="0 0 0" rpy="0 0 0" />
      <geometry>
        <mesh filename="meshes/right_hip_roll_link.STL" />
      </geometry>
      <material name="white">
        <color rgba="0.7 0.7 0.7 1" />
      </material>
    </visual>
    <collision>
      <origin xyz="0 0 0" rpy="0 0 0" />
      <geometry>
        <mesh filename="meshes/right_hip_roll_link.STL" />
      </geometry>
    </collision>
  </link>
  <joint name="right_hip_roll_joint" type="revolute">
    <origin xyz="0 -0.052 -0.030465" rpy="0 -0.1749001 0" />
    <parent link="right_hip_pitch_link" />
    <child link="right_hip_roll_link" />
    <axis xyz="1 0 0" />
    <limit lower="-2.9115673" upper="0.46806732" effort="139" velocity="20" />
  </joint>
  <link name="right_hip_yaw_link">
    <inertial>
      <origin xyz="-0.057709 0.010981 -0.15078" rpy="0 0 0" />
      <mass value="1.9283269" />
      <inertia ixx="0.0065456609" ixy="0.00061305503" ixz="-0.0027132596" iyy="0.0086246801" iyz="0.00080124325" izz="0.0035677476" />
    </inertial>
    <visual>
      <origin xyz="0 0 0" rpy="0 0 0" />
      <geometry>
        <mesh filename="meshes/right_hip_yaw_link.STL" />
      </geometry>
      <material name="white">
        <color rgba="0.7 0.7 0.7 1" />
      </material>
    </visual>
    <collision>
      <origin xyz="0 0 0" rpy="0 0 0" />
      <geometry>
        <mesh filename="meshes/right_hip_yaw_link.STL" />
      </geometry>
    </collision>
  </link>
  <joint name="right_hip_yaw_joint" type="revolute">
    <origin xyz="0.025001 0 -0.12412" rpy="0 0 0" />
    <parent link="right_hip_roll_link" />
    <child link="right_hip_yaw_link" />
    <axis xyz="0 0 1" />
    <limit lower="-2.6698601" upper="2.6698601" effort="88" velocity="32" />
  </joint>
  <link name="right_knee_link">
    <inertial>
      <origin xyz="0.005457 -0.003964 -0.12074" rpy="0 0 0" />
      <mass value="2.1889117" />
      <inertia ixx="0.012835511" ixy="-5.4653663e-05" ixz="5.086784e-05" iyy="0.012776596" iyz="0.00080962684" izz="0.0017184984" />
    </inertial>
    <visual>
      <origin xyz="0 0 0" rpy="0 0 0" />
      <geometry>
        <mesh filename="meshes/right_knee_link.STL" />
      </geometry>
      <material name="white">
        <color rgba="0.7 0.7 0.7 1" />
      </material>
    </visual>
    <collision>
      <origin xyz="0 0 0" rpy="0 0 0" />
      <geometry>
        <mesh filename="meshes/right_knee_link.STL" />
      </geometry>
    </collision>
  </link>
  <joint name="right_knee_joint" type="revolute">
    <origin xyz="-0.073769784 -0.0020252691 -0.16713724" rpy="0 0.1749001 0" />
    <parent link="right_hip_yaw_link" />
    <child link="right_knee_link" />
    <axis xyz="0 1 0" />
    <limit lower="-0.040064668" upper="2.8325977" effort="139" velocity="20" />
  </joint>
  <link name="right_ankle_pitch_link">
    <inertial>
      <origin xyz="-0.007269 0 0.011137" rpy="0 0 0" />
      <mass value="0.083840302" />
      <inertia ixx="9.5170049e-06" ixy="-6.0699478e-13" ixz="-3.2856278e-06" iyy="2.1413268e-05" iyz="-6.0908652e-13" izz="1.4275515e-05" />
    </inertial>
    <visual>
      <origin xyz="0 0 0" rpy="0 0 0" />
      <geometry>
        <mesh filename="meshes/right_ankle_pitch_link.STL" />
      </geometry>
      <material name="white">
        <color rgba="0.7 0.7 0.7 1" />
      </material>
    </visual>
    <collision>
      <origin xyz="0 0 0" rpy="0 0 0" />
      <geometry>
        <mesh filename="meshes/right_ankle_pitch_link.STL" />
      </geometry>
    </collision>
  </link>
  <joint name="right_ankle_pitch_joint" type="revolute">
    <origin xyz="0 8.9011373e-05 -0.28274977" rpy="0 0 0" />
    <parent link="right_knee_link" />
    <child link="right_ankle_pitch_link" />
    <axis xyz="0 1 0" />
    <limit lower="-0.85045709" upper="0.50138709" effort="50" velocity="37" />
  </joint>
  <link name="right_ankle_roll_link">
    <inertial>
      <origin xyz="0.026505 0 -0.016425" rpy="0 0 0" />
      <mass value="0.68885005" />
      <inertia ixx="0.000252767" ixy="-2.2659798e-07" ixz="0.00010094806" iyy="0.0018310094" iyz="1.1329816e-07" izz="0.0018883369" />
    </inertial>
    <visual>
      <origin xyz="0 0 0" rpy="0 0 0" />
      <geometry>
        <mesh filename="meshes/right_ankle_roll_link.STL" />
      </geometry>
      <material name="dark">
        <color rgba="0.2 0.2 0.2 1" />
      </material>
    </visual>
    <collision>
      <origin xyz="-0.05 0.025 -0.03" rpy="0 0 0" />
      <geometry>
        <sphere radius="0.005" />
      </geometry>
    </collision>
    <collision>
      <origin xyz="-0.05 -0.025 -0.03" rpy="0 0 0" />
      <geometry>
        <sphere radius="0.005" />
      </geometry>
    </collision>
    <collision>
      <origin xyz="0.12 0.03 -0.03" rpy="0 0 0" />
      <geometry>
        <sphere radius="0.005" />
      </geometry>
    </collision>
    <collision>
      <origin xyz="0.12 -0.03 -0.03" rpy="0 0 0" />
      <geometry>
        <sphere radius="0.005" />
      </geometry>
    </collision>
  </link>
  <joint name="right_ankle_roll_joint" type="revolute">
    <origin xyz="0 0 -0.017558" rpy="0 0 0" />
    <parent link="right_ankle_pitch_link" />
    <child link="right_ankle_roll_link" />
    <axis xyz="1 0 0" />
    <limit lower="-0.25347018" upper="0.25347018" effort="50" velocity="37" />
  </joint>
  <joint name="waist_yaw_joint" type="fixed">
    <origin xyz="-0.0039635 0 0.044" rpy="0 0 0" />
    <parent link="pelvis" />
    <child link="torso_link" />
    <axis xyz="0 0 1" />
    <limit lower="-2.618" upper="2.618" effort="88" velocity="32" />
  </joint>
  <link name="torso_link">
    <inertial>
      <origin xyz="0.000931 0.000346 0.15082" rpy="0 0 0" />
      <mass value="6.78" />
      <inertia ixx="0.05905" ixy="3.3302E-05" ixz="-0.0017715" iyy="0.047014" iyz="-2.2399E-05" izz="0.025652" />
    </inertial>
    <visual>
      <origin xyz="0.0039635 0 -0.044" rpy="0 0 0" />
      <geometry>
        <mesh filename="meshes/torso_link_23dof_rev_1_0.STL" />
      </geometry>
      <material name="white">
        <color rgba="0.7 0.7 0.7 1" />
      </material>
    </visual>
    <collision>
      <origin xyz="0.0039635 0 -0.044" rpy="0 0 0" />
      <geometry>
        <mesh filename="meshes/torso_link_23dof_rev_1_0.STL" />
      </geometry>
    </collision>
  </link>
  <joint name="logo_joint" type="fixed">
    <origin xyz="0.0039635 0 -0.044" rpy="0 0 0" />
    <parent link="torso_link" />
    <child link="logo_link" />
  </joint>
  <link name="logo_link">
    <inertial>
      <origin xyz="0 0 0" rpy="0 0 0" />
      <mass value="0.001" />
      <inertia ixx="1e-7" ixy="0" ixz="0" iyy="1e-7" iyz="0" izz="1e-7" />
    </inertial>
    <visual>
      <origin xyz="0 0 0" rpy="0 0 0" />
      <geometry>
        <mesh filename="meshes/logo_link.STL" />
      </geometry>
      <material name="dark">
        <color rgba="0.2 0.2 0.2 1" />
      </material>
    </visual>
    <collision>
      <origin xyz="0 0 0" rpy="0 0 0" />
      <geometry>
        <mesh filename="meshes/logo_link.STL" />
      </geometry>
    </collision>
  </link>
  <link name="head_link">
    <inertial>
      <origin xyz="0.005267 0.000299 0.449869" rpy="0 0 0" />
      <mass value="1.036" />
      <inertia ixx="0.004085051" ixy="-2.543E-06" ixz="-6.9455E-05" iyy="0.004185212" iyz="-3.726E-06" izz="0.001807911" />
    </inertial>
    <visual>
      <origin xyz="0 0 0" rpy="0 0 0" />
      <geometry>
        <mesh filename="meshes/head_link.STL" />
      </geometry>
      <material name="dark">
        <color rgba="0.2 0.2 0.2 1" />
      </material>
    </visual>
    <collision>
      <origin xyz="0 0 0" rpy="0 0 0" />
      <geometry>
        <mesh filename="meshes/head_link.STL" />
      </geometry>
    </collision>
  </link>
  <joint name="head_joint" type="fixed">
    <origin xyz="0.0039635 0 -0.044" rpy="0 0 0" />
    <parent link="torso_link" />
    <child link="head_link" />
  </joint>
  <link name="imu_in_torso" />
  <joint name="imu_in_torso_joint" type="fixed">
    <origin xyz="-0.03959 -0.00224 0.14792" rpy="0 0 0" />
    <parent link="torso_link" />
    <child link="imu_in_torso" />
  </joint>
  <link name="imu_in_pelvis" />
  <joint name="imu_in_pelvis_joint" type="fixed">
    <origin xyz="0.04525 0 -0.08339" rpy="0 0 0" />
    <parent link="pelvis" />
    <child link="imu_in_pelvis" />
  </joint>
  <link name="d435_link" />
  <joint name="d435_joint" type="fixed">
    <origin xyz="0.0576235 0.01753 0.42987" rpy="0 0.8307767239493009 0" />
    <parent link="torso_link" />
    <child link="d435_link" />
  </joint>
  <link name="mid360_link" />
  <joint name="mid360_joint" type="fixed">
    <origin xyz="0.0002835 0.00003 0.41618" rpy="0 0.04014257279586953 0" />
    <parent link="torso_link" />
    <child link="mid360_link" />
  </joint>
  <link name="left_shoulder_pitch_link">
    <inertial>
      <origin xyz="0 0.035892 -0.011628" rpy="0 0 0" />
      <mass value="0.718" />
      <inertia ixx="0.0004291" ixy="-9.2E-06" ixz="6.4E-06" iyy="0.000453" iyz="2.26E-05" izz="0.000423" />
    </inertial>
    <visual>
      <origin xyz="0 0 0" rpy="0 0 0" />
      <geometry>
        <mesh filename="meshes/left_shoulder_pitch_link.STL" />
      </geometry>
      <material name="white">
        <color rgba="0.7 0.7 0.7 1" />
      </material>
    </visual>
    <collision>
      <origin xyz="0 0.04 -0.01" rpy="0 1.5707963267948966 0" />
      <geometry>
        <cylinder radius="0.03" length="0.05" />
      </geometry>
    </collision>
  </link>
  <joint name="left_shoulder_pitch_joint" type="fixed">
    <origin xyz="0.0039563 0.10022 0.24778" rpy="0.27931 5.4949E-05 -0.00019159" />
    <parent link="torso_link" />
    <child link="left_shoulder_pitch_link" />
    <axis xyz="0 1 0" />
    <limit lower="-3.0892" upper="2.6704" effort="25" velocity="37" />
  </joint>
  <link name="left_shoulder_roll_link">
    <inertial>
      <origin xyz="-0.000227 0.00727 -0.063243" rpy="0 0 0" />
      <mass value="0.643" />
      <inertia ixx="0.0006177" ixy="-1E-06" ixz="8.7E-06" iyy="0.0006912" iyz="-5.3E-06" izz="0.0003894" />
    </inertial>
    <visual>
      <origin xyz="0 0 0" rpy="0 0 0" />
      <geometry>
        <mesh filename="meshes/left_shoulder_roll_link.STL" />
      </geometry>
      <material name="white">
        <color rgba="0.7 0.7 0.7 1" />
      </material>
    </visual>
    <collision>
      <origin xyz="-0.004 0.006 -0.053" rpy="0 0 0" />
      <geometry>
        <cylinder radius="0.03" length="0.03" />
      </geometry>
    </collision>
  </link>
  <joint name="left_shoulder_roll_joint" type="fixed">
    <origin xyz="0 0.038 -0.013831" rpy="-0.27925 0 0" />
    <parent link="left_shoulder_pitch_link" />
    <child link="left_shoulder_roll_link" />
    <axis xyz="1 0 0" />
    <limit lower="-1.5882" upper="2.2515" effort="25" velocity="37" />
  </joint>
  <link name="left_shoulder_yaw_link">
    <inertial>
      <origin xyz="0.010773 -0.002949 -0.072009" rpy="0 0 0" />
      <mass value="0.734" />
      <inertia ixx="0.0009988" ixy="7.9E-06" ixz="0.0001412" iyy="0.0010605" iyz="-2.86E-05" izz="0.0004354" />
    </inertial>
    <visual>
      <origin xyz="0 0 0" rpy="0 0 0" />
      <geometry>
        <mesh filename="meshes/left_shoulder_yaw_link.STL" />
      </geometry>
      <material name="white">
        <color rgba="0.7 0.7 0.7 1" />
      </material>
    </visual>
    <collision>
      <origin xyz="0 0 0" rpy="0 0 0" />
      <geometry>
        <mesh filename="meshes/left_shoulder_yaw_link.STL" />
      </geometry>
    </collision>
  </link>
  <joint name="left_shoulder_yaw_joint" type="fixed">
    <origin xyz="0 0.00624 -0.1032" rpy="0 0 0" />
    <parent link="left_shoulder_roll_link" />
    <child link="left_shoulder_yaw_link" />
    <axis xyz="0 0 1" />
    <limit lower="-2.618" upper="2.618" effort="25" velocity="37" />
  </joint>
  <link name="left_elbow_link">
    <inertial>
      <origin xyz="0.064956 0.004454 -0.010062" rpy="0 0 0" />
      <mass value="0.6" />
      <inertia ixx="0.0002891" ixy="6.53E-05" ixz="1.72E-05" iyy="0.0004152" iyz="-5.6E-06" izz="0.0004197" />
    </inertial>
    <visual>
      <origin xyz="0 0 0" rpy="0 0 0" />
      <geometry>
        <mesh filename="meshes/left_elbow_link.STL" />
      </geometry>
      <material name="white">
        <color rgba="0.7 0.7 0.7 1" />
      </material>
    </visual>
    <collision>
      <origin xyz="0 0 0" rpy="0 0 0" />
      <geometry>
        <mesh filename="meshes/left_elbow_link.STL" />
      </geometry>
    </collision>
  </link>
  <joint name="left_elbow_joint" type="fixed">
    <origin xyz="0.015783 0 -0.080518" rpy="0 0 0" />
    <parent link="left_shoulder_yaw_link" />
    <child link="left_elbow_link" />
    <axis xyz="0 1 0" />
    <limit lower="-1.0472" upper="2.0944" effort="25" velocity="37" />
  </joint>
  <joint name="left_wrist_roll_joint" type="fixed">
    <origin xyz="0.100 0.00188791 -0.010" rpy="0 0 0" />
    <axis xyz="1 0 0" />
    <parent link="left_elbow_link" />
    <child link="left_wrist_roll_rubber_hand" />
    <limit effort="25" velocity="37" lower="-1.972222054" upper="1.972222054" />
  </joint>
  <link name="left_wrist_roll_rubber_hand">
    <inertial>
      <origin xyz="0.10794656650 0.00163511945 0.00202244863" rpy="0 0 0" />
      <mass value="0.35692864" />
      <inertia ixx="0.00019613494735" ixy="-0.00000419816908" ixz="-0.00003950860580" iyy="0.00200280358206" iyz="0.00000249774203" izz="0.00194181412808" />
    </inertial>
    <visual>
      <origin xyz="0 0 0" rpy="0 0 0" />
      <geometry>
        <mesh filename="meshes/left_wrist_roll_rubber_hand.STL" />
      </geometry>
      <material name="white">
        <color rgba="0.7 0.7 0.7 1" />
      </material>
    </visual>
    <collision>
      <origin xyz="0 0 0" rpy="0 0 0" />
      <geometry>
        <mesh filename="meshes/left_wrist_roll_rubber_hand.STL" />
      </geometry>
    </collision>
  </link>
  <link name="right_shoulder_pitch_link">
    <inertial>
      <origin xyz="0 -0.035892 -0.011628" rpy="0 0 0" />
      <mass value="0.718" />
      <inertia ixx="0.0004291" ixy="9.2E-06" ixz="6.4E-06" iyy="0.000453" iyz="-2.26E-05" izz="0.000423" />
    </inertial>
    <visual>
      <origin xyz="0 0 0" rpy="0 0 0" />
      <geometry>
        <mesh filename="meshes/right_shoulder_pitch_link.STL" />
      </geometry>
      <material name="white">
        <color rgba="0.7 0.7 0.7 1" />
      </material>
    </visual>
    <collision>
      <origin xyz="0 -0.04 -0.01" rpy="0 1.5707963267948966 0" />
      <geometry>
        <cylinder radius="0.03" length="0.05" />
      </geometry>
    </collision>
  </link>
  <joint name="right_shoulder_pitch_joint" type="fixed">
    <origin xyz="0.0039563 -0.10021 0.24778" rpy="-0.27931 5.4949E-05 0.00019159" />
    <parent link="torso_link" />
    <child link="right_shoulder_pitch_link" />
    <axis xyz="0 1 0" />
    <limit lower="-3.0892" upper="2.6704" effort="25" velocity="37" />
  </joint>
  <link name="right_shoulder_roll_link">
    <inertial>
      <origin xyz="-0.000227 -0.00727 -0.063243" rpy="0 0 0" />
      <mass value="0.643" />
      <inertia ixx="0.0006177" ixy="1E-06" ixz="8.7E-06" iyy="0.0006912" iyz="5.3E-06" izz="0.0003894" />
    </inertial>
    <visual>
      <origin xyz="0 0 0" rpy="0 0 0" />
      <geometry>
        <mesh filename="meshes/right_shoulder_roll_link.STL" />
      </geometry>
      <material name="white">
        <color rgba="0.7 0.7 0.7 1" />
      </material>
    </visual>
    <collision>
      <origin xyz="-0.004 -0.006 -0.053" rpy="0 0 0" />
      <geometry>
        <cylinder radius="0.03" length="0.03" />
      </geometry>
    </collision>
  </link>
  <joint name="right_shoulder_roll_joint" type="fixed">
    <origin xyz="0 -0.038 -0.013831" rpy="0.27925 0 0" />
    <parent link="right_shoulder_pitch_link" />
    <child link="right_shoulder_roll_link" />
    <axis xyz="1 0 0" />
    <limit lower="-2.2515" upper="1.5882" effort="25" velocity="37" />
  </joint>
  <link name="right_shoulder_yaw_link">
    <inertial>
      <origin xyz="0.010773 0.002949 -0.072009" rpy="0 0 0" />
      <mass value="0.734" />
      <inertia ixx="0.0009988" ixy="-7.9E-06" ixz="0.0001412" iyy="0.0010605" iyz="2.86E-05" izz="0.0004354" />
    </inertial>
    <visual>
      <origin xyz="0 0 0" rpy="0 0 0" />
      <geometry>
        <mesh filename="meshes/right_shoulder_yaw_link.STL" />
      </geometry>
      <material name="white">
        <color rgba="0.7 0.7 0.7 1" />
      </material>
    </visual>
    <collision>
      <origin xyz="0 0 0" rpy="0 0 0" />
      <geometry>
        <mesh filename="meshes/right_shoulder_yaw_link.STL" />
      </geometry>
    </collision>
  </link>
  <joint name="right_shoulder_yaw_joint" type="fixed">
    <origin xyz="0 -0.00624 -0.1032" rpy="0 0 0" />
    <parent link="right_shoulder_roll_link" />
    <child link="right_shoulder_yaw_link" />
    <axis xyz="0 0 1" />
    <limit lower="-2.618" upper="2.618" effort="25" velocity="37" />
  </joint>
  <link name="right_elbow_link">
    <inertial>
      <origin xyz="0.064956 -0.004454 -0.010062" rpy="0 0 0" />
      <mass value="0.6" />
      <inertia ixx="0.0002891" ixy="-6.53E-05" ixz="1.72E-05" iyy="0.0004152" iyz="5.6E-06" izz="0.0004197" />
    </inertial>
    <visual>
      <origin xyz="0 0 0" rpy="0 0 0" />
      <geometry>
        <mesh filename="meshes/right_elbow_link.STL" />
      </geometry>
      <material name="white">
        <color rgba="0.7 0.7 0.7 1" />
      </material>
    </visual>
    <collision>
      <origin xyz="0 0 0" rpy="0 0 0" />
      <geometry>
        <mesh filename="meshes/right_elbow_link.STL" />
      </geometry>
    </collision>
  </link>
  <joint name="right_elbow_joint" type="fixed">
    <origin xyz="0.015783 0 -0.080518" rpy="0 0 0" />
    <parent link="right_shoulder_yaw_link" />
    <child link="right_elbow_link" />
    <axis xyz="0 1 0" />
    <limit lower="-1.0472" upper="2.0944" effort="25" velocity="37" />
  </joint>
  <joint name="right_wrist_roll_joint" type="fixed">
    <origin xyz="0.100 -0.00188791 -0.010" rpy="0 0 0" />
    <axis xyz="1 0 0" />
    <parent link="right_elbow_link" />
    <child link="right_wrist_roll_rubber_hand" />
    <limit effort="25" velocity="37" lower="-1.972222054" upper="1.972222054" />
  </joint>
  <link name="right_wrist_roll_rubber_hand">
    <inertial>
      <origin xyz="0.10794656650 -0.00163511945 0.00202244863" rpy="0 0 0" />
      <mass value="0.35692864" />
      <inertia ixx="0.00019613494735" ixy="0.00000419816908" ixz="-0.00003950860580" iyy="0.00200280358206" iyz="-0.00000249774203" izz="0.00194181412808" />
    </inertial>
    <visual>
      <origin xyz="0 0 0" rpy="0 0 0" />
      <geometry>
        <mesh filename="meshes/right_wrist_roll_rubber_hand.STL" />
      </geometry>
      <material name="white">
        <color rgba="0.7 0.7 0.7 1" />
      </material>
    </visual>
    <collision>
      <origin xyz="0 0 0" rpy="0 0 0" />
      <geometry>
        <mesh filename="meshes/right_wrist_roll_rubber_hand.STL" />
      </geometry>
    </collision>
  </link>
</robot>
