<?xml version='1.0' encoding='UTF-8'?>
<robot name="g1_12dof">
  <mujoco>
    <compiler meshdir="meshes" discardvisual="false" />
  </mujoco>
  <link name="pelvis">
    <inertial>
      <origin xyz="0 0 -0.07605" rpy="0 0 0" />
      <mass value="3.9674102" />
      <inertia ixx="0.01097618949" ixy="0" ixz="2.185041039e-06" iyy="0.009685870729" iyz="0" izz="0.008239061412" />
    </inertial>
    <visual>
      <origin xyz="0 0 0" rpy="0 0 0" />
      <geometry>
        <mesh filename="meshes/pelvis.STL" />
      </geometry>
      <material name="dark">
        <color rgba="0.2 0.2 0.2 1" />
      </material>
    </visual>
  </link>
  <link name="pelvis_contour_link">
    <inertial>
      <origin xyz="0 0 0" rpy="0 0 0" />
      <mass value="0.001" />
      <inertia ixx="1e-7" ixy="0" ixz="0" iyy="1e-7" iyz="0" izz="1e-7" />
    </inertial>
    <visual>
      <origin xyz="0 0 0" rpy="0 0 0" />
      <geometry>
        <mesh filename="meshes/pelvis_contour_link.STL" />
      </geometry>
      <material name="white">
        <color rgba="0.7 0.7 0.7 1" />
      </material>
    </visual>
    <collision>
      <origin xyz="0 0 0" rpy="0 0 0" />
      <geometry>
        <mesh filename="meshes/pelvis_contour_link.STL" />
      </geometry>
    </collision>
  </link>
  <joint name="pelvis_contour_joint" type="fixed">
    <parent link="pelvis" />
    <child link="pelvis_contour_link" />
  </joint>
  <link name="left_hip_pitch_link">
    <inertial>
      <origin xyz="0.002741 0.047791 -0.02606" rpy="0 0 0" />
      <mass value="1.6937453" />
      <inertia ixx="0.002273028404" ixy="4.617024335e-05" ixz="-4.315914053e-05" iyy="0.00178159133" iyz="0.0002145410765" izz="0.001608327454" />
    </inertial>
    <visual>
      <origin xyz="0 0 0" rpy="0 0 0" />
      <geometry>
        <mesh filename="meshes/left_hip_pitch_link.STL" />
      </geometry>
      <material name="dark">
        <color rgba="0.2 0.2 0.2 1" />
      </material>
    </visual>
    <collision>
      <origin xyz="0 0 0" rpy="0 0 0" />
      <geometry>
        <mesh filename="meshes/left_hip_pitch_link.STL" />
      </geometry>
    </collision>
  </link>
  <joint name="left_hip_pitch_joint" type="revolute">
    <origin xyz="0 0.064452 -0.093448006" rpy="0 0 0" />
    <parent link="pelvis" />
    <child link="left_hip_pitch_link" />
    <axis xyz="0 1 0" />
    <limit lower="-2.6809848" upper="3.0300848" effort="102.7" velocity="32" />
    <dynamics damping="0.000795913" friction="0.0" />
  </joint>
  <link name="left_hip_roll_link">
    <inertial>
      <origin xyz="0.029812 -0.001045 -0.087934" rpy="0 0 0" />
      <mass value="1.9070318" />
      <inertia ixx="0.002983801729" ixy="-4.767579477e-06" ixz="-0.0004903079104" iyy="0.003027713645" iyz="2.308512168e-05" izz="0.002083231059" />
    </inertial>
    <visual>
      <origin xyz="0 0 0" rpy="0 0 0" />
      <geometry>
        <mesh filename="meshes/left_hip_roll_link.STL" />
      </geometry>
      <material name="white">
        <color rgba="0.7 0.7 0.7 1" />
      </material>
    </visual>
    <collision>
      <origin xyz="0 0 0" rpy="0 0 0" />
      <geometry>
        <mesh filename="meshes/left_hip_roll_link.STL" />
      </geometry>
    </collision>
  </link>
  <joint name="left_hip_roll_joint" type="revolute">
    <origin xyz="0 0.052 -0.027720482" rpy="0 -0.1749 0" />
    <parent link="left_hip_pitch_link" />
    <child link="left_hip_roll_link" />
    <axis xyz="1 0 0" />
    <limit lower="-0.66295783" upper="3.1064578" effort="166" velocity="20" />
    <dynamics damping="0.00124077" friction="0.0" />
  </joint>
  <link name="left_hip_yaw_link">
    <inertial>
      <origin xyz="-0.057709 -0.010981 -0.15078" rpy="0 0 0" />
      <mass value="2.1353738" />
      <inertia ixx="0.007249310841" ixy="-0.000678878225" ixz="-0.003004578771" iyy="0.009551549878" iyz="-0.0008872716332" izz="0.003951651395" />
    </inertial>
    <visual>
      <origin xyz="0 0 0" rpy="0 0 0" />
      <geometry>
        <mesh filename="meshes/left_hip_yaw_link.STL" />
      </geometry>
      <material name="white">
        <color rgba="0.7 0.7 0.7 1" />
      </material>
    </visual>
    <collision>
      <origin xyz="0 0 0" rpy="0 0 0" />
      <geometry>
        <mesh filename="meshes/left_hip_yaw_link.STL" />
      </geometry>
    </collision>
  </link>
  <joint name="left_hip_yaw_joint" type="revolute">
    <origin xyz="0.025001 0 -0.11293833" rpy="0 0 0" />
    <parent link="left_hip_roll_link" />
    <child link="left_hip_yaw_link" />
    <axis xyz="0 0 1" />
    <limit lower="-2.616697" upper="2.616697" effort="77.36" velocity="32" />
    <dynamics damping="0.00107096" friction="0.0" />
  </joint>
  <link name="left_knee_link">
    <inertial>
      <origin xyz="0.005457 0.003964 -0.12074" rpy="0 0 0" />
      <mass value="2.4239378" />
      <inertia ixx="0.01421460227" ixy="6.047298179e-05" ixz="-5.63327154e-05" iyy="0.01414936171" iyz="-0.0008965558669" izz="0.001903959289" />
    </inertial>
    <visual>
      <origin xyz="0 0 0" rpy="0 0 0" />
      <geometry>
        <mesh filename="meshes/left_knee_link.STL" />
      </geometry>
      <material name="white">
        <color rgba="0.7 0.7 0.7 1" />
      </material>
    </visual>
    <collision>
      <origin xyz="0 0 0" rpy="0 0 0" />
      <geometry>
        <mesh filename="meshes/left_knee_link.STL" />
      </geometry>
    </collision>
  </link>
  <joint name="left_knee_joint" type="revolute">
    <origin xyz="-0.078273 0.0021489 -0.16136387" rpy="0 0.1749 0" />
    <parent link="left_hip_yaw_link" />
    <child link="left_knee_link" />
    <axis xyz="0 1 0" />
    <limit lower="0.056207081" upper="2.7363259" effort="158.3" velocity="20" />
    <dynamics damping="0.000822401" friction="0.0" />
  </joint>
  <link name="left_ankle_pitch_link">
    <inertial>
      <origin xyz="-0.007269 0 0.011137" rpy="0 0 0" />
      <mass value="0.092842337" />
      <inertia ixx="0.01254717375" ixy="0" ixz="-3.638415917e-06" iyy="0.01254717375" iyz="0" izz="0.01254717375" />
    </inertial>
    <visual>
      <origin xyz="0 0 0" rpy="0 0 0" />
      <geometry>
        <mesh filename="meshes/left_ankle_pitch_link.STL" />
      </geometry>
      <material name="white">
        <color rgba="0.7 0.7 0.7 1" />
      </material>
    </visual>
    <collision>
      <origin xyz="0 0 0" rpy="0 0 0" />
      <geometry>
        <mesh filename="meshes/left_ankle_pitch_link.STL" />
      </geometry>
    </collision>
  </link>
  <joint name="left_ankle_pitch_joint" type="revolute">
    <origin xyz="0 -9.4445e-05 -0.27298283" rpy="0 0 0" />
    <parent link="left_knee_link" />
    <child link="left_ankle_pitch_link" />
    <axis xyz="0 1 0" />
    <limit lower="-0.92894963" upper="0.57987963" effort="57.13" velocity="37" />
    <dynamics damping="0.00117647" friction="0.0" />
  </joint>
  <link name="left_ankle_roll_link">
    <inertial>
      <origin xyz="0.026505 0 -0.016425" rpy="0 0 0" />
      <mass value="0.76281272" />
      <inertia ixx="0.01254731263" ixy="2.509252356e-07" ixz="0.0001117871925" iyy="0.01254731263" iyz="-1.254626178e-07" izz="0.01254731263" />
    </inertial>
    <visual>
      <origin xyz="0 0 0" rpy="0 0 0" />
      <geometry>
        <mesh filename="meshes/left_ankle_roll_link.STL" />
      </geometry>
      <material name="dark">
        <color rgba="0.2 0.2 0.2 1" />
      </material>
    </visual>
    <collision name="left_ankle_roll_link_col_0">
      <origin xyz="-0.05 0.025 -0.03" rpy="0 0 0" />
      <geometry>
        <sphere radius="0.005" />
      </geometry>
    </collision>
    <collision name="left_ankle_roll_link_col_1">
      <origin xyz="-0.05 -0.025 -0.03" rpy="0 0 0" />
      <geometry>
        <sphere radius="0.005" />
      </geometry>
    </collision>
    <collision name="left_ankle_roll_link_col_2">
      <origin xyz="0.12 0.03 -0.03" rpy="0 0 0" />
      <geometry>
        <sphere radius="0.005" />
      </geometry>
    </collision>
    <collision name="left_ankle_roll_link_col_3">
      <origin xyz="0.12 -0.03 -0.03" rpy="0 0 0" />
      <geometry>
        <sphere radius="0.005" />
      </geometry>
    </collision>
  </link>
  <joint name="left_ankle_roll_joint" type="revolute">
    <origin xyz="0 0 -0.015976242" rpy="0 0 0" />
    <parent link="left_ankle_pitch_link" />
    <child link="left_ankle_roll_link" />
    <axis xyz="1 0 0" />
    <limit lower="-0.26243805" upper="0.26243805" effort="42.99" velocity="37" />
    <dynamics damping="0.0011125" friction="0.0" />
  </joint>
  <link name="right_hip_pitch_link">
    <inertial>
      <origin xyz="0.002741 -0.047791 -0.02606" rpy="0 0 0" />
      <mass value="1.5411898" />
      <inertia ixx="0.002068637203" ixy="-4.201169193e-05" ixz="-3.927179898e-05" iyy="0.001621463841" iyz="-0.0001952173728" izz="0.001463805834" />
    </inertial>
    <visual>
      <origin xyz="0 0 0" rpy="0 0 0" />
      <geometry>
        <mesh filename="meshes/right_hip_pitch_link.STL" />
      </geometry>
      <material name="dark">
        <color rgba="0.2 0.2 0.2 1" />
      </material>
    </visual>
    <collision>
      <origin xyz="0 0 0" rpy="0 0 0" />
      <geometry>
        <mesh filename="meshes/right_hip_pitch_link.STL" />
      </geometry>
    </collision>
  </link>
  <joint name="right_hip_pitch_joint" type="revolute">
    <origin xyz="0 -0.064452 -0.099992398" rpy="0 0 0" />
    <parent link="pelvis" />
    <child link="right_hip_pitch_link" />
    <axis xyz="0 1 0" />
    <limit lower="-2.4797971" upper="2.8288971" effort="100.6" velocity="32" />
    <dynamics damping="0.00112718" friction="0.0" />
  </joint>
  <link name="right_hip_roll_link">
    <inertial>
      <origin xyz="0.029812 0.001045 -0.087934" rpy="0 0 0" />
      <mass value="1.7352655" />
      <inertia ixx="0.002715035534" ixy="4.338163841e-06" ixz="-0.0004461459024" iyy="0.002754992307" iyz="-2.100584597e-05" izz="0.001895579217" />
    </inertial>
    <visual>
      <origin xyz="0 0 0" rpy="0 0 0" />
      <geometry>
        <mesh filename="meshes/right_hip_roll_link.STL" />
      </geometry>
      <material name="white">
        <color rgba="0.7 0.7 0.7 1" />
      </material>
    </visual>
    <collision>
      <origin xyz="0 0 0" rpy="0 0 0" />
      <geometry>
        <mesh filename="meshes/right_hip_roll_link.STL" />
      </geometry>
    </collision>
  </link>
  <joint name="right_hip_roll_joint" type="revolute">
    <origin xyz="0 -0.052 -0.029661815" rpy="0 -0.1749 0" />
    <parent link="right_hip_pitch_link" />
    <child link="right_hip_roll_link" />
    <axis xyz="1 0 0" />
    <limit lower="-3.0189559" upper="0.57545592" effort="145.7" velocity="20" />
    <dynamics damping="0.000833648" friction="0.0" />
  </joint>
  <link name="right_hip_yaw_link">
    <inertial>
      <origin xyz="-0.057709 0.010981 -0.15078" rpy="0 0 0" />
      <mass value="1.9430408" />
      <inertia ixx="0.006596665455" ixy="0.0006177316985" ixz="-0.002733956517" iyy="0.008691541941" iyz="0.0008073551232" izz="0.003596026024" />
    </inertial>
    <visual>
      <origin xyz="0 0 0" rpy="0 0 0" />
      <geometry>
        <mesh filename="meshes/right_hip_yaw_link.STL" />
      </geometry>
      <material name="white">
        <color rgba="0.7 0.7 0.7 1" />
      </material>
    </visual>
    <collision>
      <origin xyz="0 0 0" rpy="0 0 0" />
      <geometry>
        <mesh filename="meshes/right_hip_yaw_link.STL" />
      </geometry>
    </collision>
  </link>
  <joint name="right_hip_yaw_joint" type="revolute">
    <origin xyz="0.025001 0 -0.12084768" rpy="0 0 0" />
    <parent link="right_hip_roll_link" />
    <child link="right_hip_yaw_link" />
    <axis xyz="0 0 1" />
    <limit lower="-2.7096196" upper="2.7096196" effort="72.57" velocity="32" />
    <dynamics damping="0.000774123" friction="0.0" />
  </joint>
  <link name="right_knee_link">
    <inertial>
      <origin xyz="0.005457 -0.003964 -0.12074" rpy="0 0 0" />
      <mass value="2.2056138" />
      <inertia ixx="0.0129343508" ixy="-5.502618346e-05" ixz="5.125883065e-05" iyy="0.01287498645" iyz="0.0008158031265" izz="0.001732526784" />
    </inertial>
    <visual>
      <origin xyz="0 0 0" rpy="0 0 0" />
      <geometry>
        <mesh filename="meshes/right_knee_link.STL" />
      </geometry>
      <material name="white">
        <color rgba="0.7 0.7 0.7 1" />
      </material>
    </visual>
    <collision>
      <origin xyz="0 0 0" rpy="0 0 0" />
      <geometry>
        <mesh filename="meshes/right_knee_link.STL" />
      </geometry>
    </collision>
  </link>
  <joint name="right_knee_joint" type="revolute">
    <origin xyz="-0.078273 -0.0021489 -0.17266457" rpy="0 0.1749 0" />
    <parent link="right_hip_yaw_link" />
    <child link="right_knee_link" />
    <axis xyz="0 1 0" />
    <limit lower="-0.02088723" upper="2.8134202" effort="156.7" velocity="20" />
    <dynamics damping="0.00085719" friction="0.0" />
  </joint>
  <link name="right_ankle_pitch_link">
    <inertial>
      <origin xyz="-0.007269 0 0.011137" rpy="0 0 0" />
      <mass value="0.084480033" />
      <inertia ixx="0.01141736707" ixy="0" ixz="-3.310703984e-06" iyy="0.01141736707" iyz="0" izz="0.01141736707" />
    </inertial>
    <visual>
      <origin xyz="0 0 0" rpy="0 0 0" />
      <geometry>
        <mesh filename="meshes/right_ankle_pitch_link.STL" />
      </geometry>
      <material name="white">
        <color rgba="0.7 0.7 0.7 1" />
      </material>
    </visual>
    <collision>
      <origin xyz="0 0 0" rpy="0 0 0" />
      <geometry>
        <mesh filename="meshes/right_ankle_pitch_link.STL" />
      </geometry>
    </collision>
  </link>
  <joint name="right_ankle_pitch_joint" type="revolute">
    <origin xyz="0 9.4445e-05 -0.29210048" rpy="0 0 0" />
    <parent link="right_knee_link" />
    <child link="right_ankle_pitch_link" />
    <axis xyz="0 1 0" />
    <limit lower="-0.86466226" upper="0.51559226" effort="49.38" velocity="37" />
    <dynamics damping="0.00112301" friction="0.0" />
  </joint>
  <link name="right_ankle_roll_link">
    <inertial>
      <origin xyz="0.026505 0 -0.016425" rpy="0 0 0" />
      <mass value="0.69410621" />
      <inertia ixx="0.01141729436" ixy="-2.283244127e-07" ixz="0.0001017185258" iyy="0.01141729436" iyz="1.141622063e-07" izz="0.01141729436" />
    </inertial>
    <visual>
      <origin xyz="0 0 0" rpy="0 0 0" />
      <geometry>
        <mesh filename="meshes/right_ankle_roll_link.STL" />
      </geometry>
      <material name="dark">
        <color rgba="0.2 0.2 0.2 1" />
      </material>
    </visual>
    <collision name="right_ankle_roll_link_col_0">
      <origin xyz="-0.05 0.025 -0.03" rpy="0 0 0" />
      <geometry>
        <sphere radius="0.005" />
      </geometry>
    </collision>
    <collision name="right_ankle_roll_link_col_1">
      <origin xyz="-0.05 -0.025 -0.03" rpy="0 0 0" />
      <geometry>
        <sphere radius="0.005" />
      </geometry>
    </collision>
    <collision name="right_ankle_roll_link_col_2">
      <origin xyz="0.12 0.03 -0.03" rpy="0 0 0" />
      <geometry>
        <sphere radius="0.005" />
      </geometry>
    </collision>
    <collision name="right_ankle_roll_link_col_3">
      <origin xyz="0.12 -0.03 -0.03" rpy="0 0 0" />
      <geometry>
        <sphere radius="0.005" />
      </geometry>
    </collision>
  </link>
  <joint name="right_ankle_roll_joint" type="revolute">
    <origin xyz="0 0 -0.017095098" rpy="0 0 0" />
    <parent link="right_ankle_pitch_link" />
    <child link="right_ankle_roll_link" />
    <axis xyz="1 0 0" />
    <limit lower="-0.27765817" upper="0.27765817" effort="42.59" velocity="37" />
    <dynamics damping="0.0011156" friction="0.0" />
  </joint>
  <joint name="waist_yaw_joint" type="fixed">
    <origin xyz="-0.0039635 0 0.044" rpy="0 0 0" />
    <parent link="pelvis" />
    <child link="torso_link" />
    <axis xyz="0 0 1" />
    <limit lower="-2.618" upper="2.618" effort="88" velocity="32" />
  </joint>
  <link name="torso_link">
    <inertial>
      <origin xyz="0.000931 0.000346 0.15082" rpy="0 0 0" />
      <mass value="6.78" />
      <inertia ixx="0.05905" ixy="3.3302E-05" ixz="-0.0017715" iyy="0.047014" iyz="-2.2399E-05" izz="0.025652" />
    </inertial>
    <visual>
      <origin xyz="0.0039635 0 -0.044" rpy="0 0 0" />
      <geometry>
        <mesh filename="meshes/torso_link_23dof_rev_1_0.STL" />
      </geometry>
      <material name="white">
        <color rgba="0.7 0.7 0.7 1" />
      </material>
    </visual>
    <collision>
      <origin xyz="0.0039635 0 -0.044" rpy="0 0 0" />
      <geometry>
        <mesh filename="meshes/torso_link_23dof_rev_1_0.STL" />
      </geometry>
    </collision>
  </link>
  <joint name="logo_joint" type="fixed">
    <origin xyz="0.0039635 0 -0.044" rpy="0 0 0" />
    <parent link="torso_link" />
    <child link="logo_link" />
  </joint>
  <link name="logo_link">
    <inertial>
      <origin xyz="0 0 0" rpy="0 0 0" />
      <mass value="0.001" />
      <inertia ixx="1e-7" ixy="0" ixz="0" iyy="1e-7" iyz="0" izz="1e-7" />
    </inertial>
    <visual>
      <origin xyz="0 0 0" rpy="0 0 0" />
      <geometry>
        <mesh filename="meshes/logo_link.STL" />
      </geometry>
      <material name="dark">
        <color rgba="0.2 0.2 0.2 1" />
      </material>
    </visual>
    <collision>
      <origin xyz="0 0 0" rpy="0 0 0" />
      <geometry>
        <mesh filename="meshes/logo_link.STL" />
      </geometry>
    </collision>
  </link>
  <link name="head_link">
    <inertial>
      <origin xyz="0.005267 0.000299 0.449869" rpy="0 0 0" />
      <mass value="1.036" />
      <inertia ixx="0.004085051" ixy="-2.543E-06" ixz="-6.9455E-05" iyy="0.004185212" iyz="-3.726E-06" izz="0.001807911" />
    </inertial>
    <visual>
      <origin xyz="0 0 0" rpy="0 0 0" />
      <geometry>
        <mesh filename="meshes/head_link.STL" />
      </geometry>
      <material name="dark">
        <color rgba="0.2 0.2 0.2 1" />
      </material>
    </visual>
    <collision>
      <origin xyz="0 0 0" rpy="0 0 0" />
      <geometry>
        <mesh filename="meshes/head_link.STL" />
      </geometry>
    </collision>
  </link>
  <joint name="head_joint" type="fixed">
    <origin xyz="0.0039635 0 -0.044" rpy="0 0 0" />
    <parent link="torso_link" />
    <child link="head_link" />
  </joint>
  <link name="imu_in_torso" />
  <joint name="imu_in_torso_joint" type="fixed">
    <origin xyz="-0.03959 -0.00224 0.14792" rpy="0 0 0" />
    <parent link="torso_link" />
    <child link="imu_in_torso" />
  </joint>
  <link name="imu_in_pelvis" />
  <joint name="imu_in_pelvis_joint" type="fixed">
    <origin xyz="0.04525 0 -0.08339" rpy="0 0 0" />
    <parent link="pelvis" />
    <child link="imu_in_pelvis" />
  </joint>
  <link name="d435_link" />
  <joint name="d435_joint" type="fixed">
    <origin xyz="0.0576235 0.01753 0.42987" rpy="0 0.8307767239493009 0" />
    <parent link="torso_link" />
    <child link="d435_link" />
  </joint>
  <link name="mid360_link" />
  <joint name="mid360_joint" type="fixed">
    <origin xyz="0.0002835 0.00003 0.41618" rpy="0 0.04014257279586953 0" />
    <parent link="torso_link" />
    <child link="mid360_link" />
  </joint>
  <link name="left_shoulder_pitch_link">
    <inertial>
      <origin xyz="0 0.035892 -0.011628" rpy="0 0 0" />
      <mass value="0.718" />
      <inertia ixx="0.0004291" ixy="-9.2E-06" ixz="6.4E-06" iyy="0.000453" iyz="2.26E-05" izz="0.000423" />
    </inertial>
    <visual>
      <origin xyz="0 0 0" rpy="0 0 0" />
      <geometry>
        <mesh filename="meshes/left_shoulder_pitch_link.STL" />
      </geometry>
      <material name="white">
        <color rgba="0.7 0.7 0.7 1" />
      </material>
    </visual>
    <collision>
      <origin xyz="0 0.04 -0.01" rpy="0 1.5707963267948966 0" />
      <geometry>
        <cylinder radius="0.03" length="0.05" />
      </geometry>
    </collision>
  </link>
  <joint name="left_shoulder_pitch_joint" type="fixed">
    <origin xyz="0.0039563 0.10022 0.24778" rpy="0.27931 5.4949E-05 -0.00019159" />
    <parent link="torso_link" />
    <child link="left_shoulder_pitch_link" />
    <axis xyz="0 1 0" />
    <limit lower="-3.0892" upper="2.6704" effort="25" velocity="37" />
  </joint>
  <link name="left_shoulder_roll_link">
    <inertial>
      <origin xyz="-0.000227 0.00727 -0.063243" rpy="0 0 0" />
      <mass value="0.643" />
      <inertia ixx="0.0006177" ixy="-1E-06" ixz="8.7E-06" iyy="0.0006912" iyz="-5.3E-06" izz="0.0003894" />
    </inertial>
    <visual>
      <origin xyz="0 0 0" rpy="0 0 0" />
      <geometry>
        <mesh filename="meshes/left_shoulder_roll_link.STL" />
      </geometry>
      <material name="white">
        <color rgba="0.7 0.7 0.7 1" />
      </material>
    </visual>
    <collision>
      <origin xyz="-0.004 0.006 -0.053" rpy="0 0 0" />
      <geometry>
        <cylinder radius="0.03" length="0.03" />
      </geometry>
    </collision>
  </link>
  <joint name="left_shoulder_roll_joint" type="fixed">
    <origin xyz="0 0.038 -0.013831" rpy="-0.27925 0 0" />
    <parent link="left_shoulder_pitch_link" />
    <child link="left_shoulder_roll_link" />
    <axis xyz="1 0 0" />
    <limit lower="-1.5882" upper="2.2515" effort="25" velocity="37" />
  </joint>
  <link name="left_shoulder_yaw_link">
    <inertial>
      <origin xyz="0.010773 -0.002949 -0.072009" rpy="0 0 0" />
      <mass value="0.734" />
      <inertia ixx="0.0009988" ixy="7.9E-06" ixz="0.0001412" iyy="0.0010605" iyz="-2.86E-05" izz="0.0004354" />
    </inertial>
    <visual>
      <origin xyz="0 0 0" rpy="0 0 0" />
      <geometry>
        <mesh filename="meshes/left_shoulder_yaw_link.STL" />
      </geometry>
      <material name="white">
        <color rgba="0.7 0.7 0.7 1" />
      </material>
    </visual>
    <collision>
      <origin xyz="0 0 0" rpy="0 0 0" />
      <geometry>
        <mesh filename="meshes/left_shoulder_yaw_link.STL" />
      </geometry>
    </collision>
  </link>
  <joint name="left_shoulder_yaw_joint" type="fixed">
    <origin xyz="0 0.00624 -0.1032" rpy="0 0 0" />
    <parent link="left_shoulder_roll_link" />
    <child link="left_shoulder_yaw_link" />
    <axis xyz="0 0 1" />
    <limit lower="-2.618" upper="2.618" effort="25" velocity="37" />
  </joint>
  <link name="left_elbow_link">
    <inertial>
      <origin xyz="0.064956 0.004454 -0.010062" rpy="0 0 0" />
      <mass value="0.6" />
      <inertia ixx="0.0002891" ixy="6.53E-05" ixz="1.72E-05" iyy="0.0004152" iyz="-5.6E-06" izz="0.0004197" />
    </inertial>
    <visual>
      <origin xyz="0 0 0" rpy="0 0 0" />
      <geometry>
        <mesh filename="meshes/left_elbow_link.STL" />
      </geometry>
      <material name="white">
        <color rgba="0.7 0.7 0.7 1" />
      </material>
    </visual>
    <collision>
      <origin xyz="0 0 0" rpy="0 0 0" />
      <geometry>
        <mesh filename="meshes/left_elbow_link.STL" />
      </geometry>
    </collision>
  </link>
  <joint name="left_elbow_joint" type="fixed">
    <origin xyz="0.015783 0 -0.080518" rpy="0 0 0" />
    <parent link="left_shoulder_yaw_link" />
    <child link="left_elbow_link" />
    <axis xyz="0 1 0" />
    <limit lower="-1.0472" upper="2.0944" effort="25" velocity="37" />
  </joint>
  <joint name="left_wrist_roll_joint" type="fixed">
    <origin xyz="0.100 0.00188791 -0.010" rpy="0 0 0" />
    <axis xyz="1 0 0" />
    <parent link="left_elbow_link" />
    <child link="left_wrist_roll_rubber_hand" />
    <limit effort="25" velocity="37" lower="-1.972222054" upper="1.972222054" />
  </joint>
  <link name="left_wrist_roll_rubber_hand">
    <inertial>
      <origin xyz="0.10794656650 0.00163511945 0.00202244863" rpy="0 0 0" />
      <mass value="0.35692864" />
      <inertia ixx="0.00019613494735" ixy="-0.00000419816908" ixz="-0.00003950860580" iyy="0.00200280358206" iyz="0.00000249774203" izz="0.00194181412808" />
    </inertial>
    <visual>
      <origin xyz="0 0 0" rpy="0 0 0" />
      <geometry>
        <mesh filename="meshes/left_wrist_roll_rubber_hand.STL" />
      </geometry>
      <material name="white">
        <color rgba="0.7 0.7 0.7 1" />
      </material>
    </visual>
    <collision>
      <origin xyz="0 0 0" rpy="0 0 0" />
      <geometry>
        <mesh filename="meshes/left_wrist_roll_rubber_hand.STL" />
      </geometry>
    </collision>
  </link>
  <link name="right_shoulder_pitch_link">
    <inertial>
      <origin xyz="0 -0.035892 -0.011628" rpy="0 0 0" />
      <mass value="0.718" />
      <inertia ixx="0.0004291" ixy="9.2E-06" ixz="6.4E-06" iyy="0.000453" iyz="-2.26E-05" izz="0.000423" />
    </inertial>
    <visual>
      <origin xyz="0 0 0" rpy="0 0 0" />
      <geometry>
        <mesh filename="meshes/right_shoulder_pitch_link.STL" />
      </geometry>
      <material name="white">
        <color rgba="0.7 0.7 0.7 1" />
      </material>
    </visual>
    <collision>
      <origin xyz="0 -0.04 -0.01" rpy="0 1.5707963267948966 0" />
      <geometry>
        <cylinder radius="0.03" length="0.05" />
      </geometry>
    </collision>
  </link>
  <joint name="right_shoulder_pitch_joint" type="fixed">
    <origin xyz="0.0039563 -0.10021 0.24778" rpy="-0.27931 5.4949E-05 0.00019159" />
    <parent link="torso_link" />
    <child link="right_shoulder_pitch_link" />
    <axis xyz="0 1 0" />
    <limit lower="-3.0892" upper="2.6704" effort="25" velocity="37" />
  </joint>
  <link name="right_shoulder_roll_link">
    <inertial>
      <origin xyz="-0.000227 -0.00727 -0.063243" rpy="0 0 0" />
      <mass value="0.643" />
      <inertia ixx="0.0006177" ixy="1E-06" ixz="8.7E-06" iyy="0.0006912" iyz="5.3E-06" izz="0.0003894" />
    </inertial>
    <visual>
      <origin xyz="0 0 0" rpy="0 0 0" />
      <geometry>
        <mesh filename="meshes/right_shoulder_roll_link.STL" />
      </geometry>
      <material name="white">
        <color rgba="0.7 0.7 0.7 1" />
      </material>
    </visual>
    <collision>
      <origin xyz="-0.004 -0.006 -0.053" rpy="0 0 0" />
      <geometry>
        <cylinder radius="0.03" length="0.03" />
      </geometry>
    </collision>
  </link>
  <joint name="right_shoulder_roll_joint" type="fixed">
    <origin xyz="0 -0.038 -0.013831" rpy="0.27925 0 0" />
    <parent link="right_shoulder_pitch_link" />
    <child link="right_shoulder_roll_link" />
    <axis xyz="1 0 0" />
    <limit lower="-2.2515" upper="1.5882" effort="25" velocity="37" />
  </joint>
  <link name="right_shoulder_yaw_link">
    <inertial>
      <origin xyz="0.010773 0.002949 -0.072009" rpy="0 0 0" />
      <mass value="0.734" />
      <inertia ixx="0.0009988" ixy="-7.9E-06" ixz="0.0001412" iyy="0.0010605" iyz="2.86E-05" izz="0.0004354" />
    </inertial>
    <visual>
      <origin xyz="0 0 0" rpy="0 0 0" />
      <geometry>
        <mesh filename="meshes/right_shoulder_yaw_link.STL" />
      </geometry>
      <material name="white">
        <color rgba="0.7 0.7 0.7 1" />
      </material>
    </visual>
    <collision>
      <origin xyz="0 0 0" rpy="0 0 0" />
      <geometry>
        <mesh filename="meshes/right_shoulder_yaw_link.STL" />
      </geometry>
    </collision>
  </link>
  <joint name="right_shoulder_yaw_joint" type="fixed">
    <origin xyz="0 -0.00624 -0.1032" rpy="0 0 0" />
    <parent link="right_shoulder_roll_link" />
    <child link="right_shoulder_yaw_link" />
    <axis xyz="0 0 1" />
    <limit lower="-2.618" upper="2.618" effort="25" velocity="37" />
  </joint>
  <link name="right_elbow_link">
    <inertial>
      <origin xyz="0.064956 -0.004454 -0.010062" rpy="0 0 0" />
      <mass value="0.6" />
      <inertia ixx="0.0002891" ixy="-6.53E-05" ixz="1.72E-05" iyy="0.0004152" iyz="5.6E-06" izz="0.0004197" />
    </inertial>
    <visual>
      <origin xyz="0 0 0" rpy="0 0 0" />
      <geometry>
        <mesh filename="meshes/right_elbow_link.STL" />
      </geometry>
      <material name="white">
        <color rgba="0.7 0.7 0.7 1" />
      </material>
    </visual>
    <collision>
      <origin xyz="0 0 0" rpy="0 0 0" />
      <geometry>
        <mesh filename="meshes/right_elbow_link.STL" />
      </geometry>
    </collision>
  </link>
  <joint name="right_elbow_joint" type="fixed">
    <origin xyz="0.015783 0 -0.080518" rpy="0 0 0" />
    <parent link="right_shoulder_yaw_link" />
    <child link="right_elbow_link" />
    <axis xyz="0 1 0" />
    <limit lower="-1.0472" upper="2.0944" effort="25" velocity="37" />
  </joint>
  <joint name="right_wrist_roll_joint" type="fixed">
    <origin xyz="0.100 -0.00188791 -0.010" rpy="0 0 0" />
    <axis xyz="1 0 0" />
    <parent link="right_elbow_link" />
    <child link="right_wrist_roll_rubber_hand" />
    <limit effort="25" velocity="37" lower="-1.972222054" upper="1.972222054" />
  </joint>
  <link name="right_wrist_roll_rubber_hand">
    <inertial>
      <origin xyz="0.10794656650 -0.00163511945 0.00202244863" rpy="0 0 0" />
      <mass value="0.35692864" />
      <inertia ixx="0.00019613494735" ixy="0.00000419816908" ixz="-0.00003950860580" iyy="0.00200280358206" iyz="-0.00000249774203" izz="0.00194181412808" />
    </inertial>
    <visual>
      <origin xyz="0 0 0" rpy="0 0 0" />
      <geometry>
        <mesh filename="meshes/right_wrist_roll_rubber_hand.STL" />
      </geometry>
      <material name="white">
        <color rgba="0.7 0.7 0.7 1" />
      </material>
    </visual>
    <collision>
      <origin xyz="0 0 0" rpy="0 0 0" />
      <geometry>
        <mesh filename="meshes/right_wrist_roll_rubber_hand.STL" />
      </geometry>
    </collision>
  </link>
</robot>